Workbook
Name AP71AJ72: 'Greenfield — Em Cobrança'!$AP$71

Sheet 🔧 Painel
A1: V&F | Sistema Seguro Garantia — Painel de Controle
A2: =TODAY() -> 46112
A4: INDICADORES
A5: BASE TOTAL | D5: PIPELINE ATIVO | G5: FOLLOW-UPS ATRASADOS
A6: =Dashboard!B5 -> 6693 | B6: empresas | D6: =Dashboard!C5 -> 1 | E6: oportunidades | G6: =COUNTIF('Greenfield — Em Cobrança'!AB4:AB6696,"*Atrasado*") -> 1 | H6: urgentes
A7: =Dashboard!B6 -> 47710321310 | B7: valor total | D7: =Dashboard!C6 -> 75813202 | E7: em pipeline | G7: ligar HOJE | H7: → ver Worklist
A9: PROPOSTAS ENVIADAS | D9: EMISSÕES (WON) | G9: CONSULTAS PENDENTES
A10: =Dashboard!E5 -> 0 | B10: propostas | D10: =Dashboard!F5 -> 0 | E10: =Dashboard!F6 -> 0 | G10: =COUNTIF('Greenfield — Em Cobrança'!S4:S6696,"")-COUNTIF('Greenfield — Em Cobrança'!W4:W6696,"") -> -6 | H10: s/ consulta
A11: =Dashboard!E6 -> 0 | B11: valor propostas | D11: convertidos ✅ | E11: =IF(Dashboard!B5=0,"-",TEXT(Dashboard!F5/Dashboard!B5,"0.0%")) -> 0,0% | G11: no pipeline, consultar Cia
A13: TOP 10 OPORTUNIDADES POR PRÊMIO ESTIMADO
A14: Empresa | B14: Valor Aberto (R$) | D14: Prêmio Estim. (R$) | E14: Estágio
A15: {=IFERROR(_xlws.SORT(_xlws.FILTER(HSTACK('Greenfield — Em Cobrança'!B4:B6696,'Greenfield — Em Cobrança'!H4:H6696,'Greenfield — Em Cobrança'!AC4:AC6696,'Greenfield — Em Cobrança'!AD4:AD6696,'Greenfield — Em Cobrança'!W4:W6696),'Greenfield — Em Cobrança'!AD4:AD6696>0),4,-1),"Nenhum prêmio estimado ainda — preencha a Taxa Estim. (%) na Greenfield")} -> Nenhum prêmio estimado ainda — preencha a Taxa Estim. (%) na Greenfield

Sheet Dashboard
A1: V&F | Dashboard — Pipeline Seguro Garantia
A2: Atualizado automaticamente | Base: 6.693 empresas Greenfield
A4: KPI | B4: Total Prospects | C4: Pipeline Ativo | D4: Consultas em Andamento | E4: Propostas Enviadas | F4: Emissões (Won) | G4: Perdidos | H4: Taxa Conversão
A5: Quantidade | B5: =COUNTA('Greenfield — Em Cobrança'!B4:B6696) -> 6693 | C5: =COUNTIFS('Greenfield — Em Cobrança'!W4:W6696,"<>",'Greenfield — Em Cobrança'!W4:W6696,"<>🗑️ Descarte",'Greenfield — Em Cobrança'!W4:W6696,"<>❌ Perdido") -> 1 | D5: =COUNTIF('Greenfield — Em Cobrança'!W4:W6696,"📞 Consulta Cia") -> 0 | E5: =COUNTIF('Greenfield — Em Cobrança'!W4:W6696,"📋 Proposta Enviada") -> 0 | F5: =COUNTIF('Greenfield — Em Cobrança'!W4:W6696,"✅ Emissão") -> 0 | G5: =COUNTIF('Greenfield — Em Cobrança'!W4:W6696,"❌ Perdido") -> 0 | H5: =IF(B5=0,"-",F5/B5) -> 0
A6: Valor (R$) | B6: =SUM('Greenfield — Em Cobrança'!H4:H6696) -> 47710321310 | C6: {=SUMPRODUCT(('Greenfield — Em Cobrança'!W4:W6696<>"")*('Greenfield — Em Cobrança'!W4:W6696<>"🗑️ Descarte")*('Greenfield — Em Cobrança'!W4:W6696<>"❌ Perdido")*'Greenfield — Em Cobrança'!H4:H6696)} -> 75813202 | D6: =SUMIF('Greenfield — Em Cobrança'!W4:W6696,"📞 Consulta Cia",'Greenfield — Em Cobrança'!H4:H6696) -> 0 | E6: =SUMIF('Greenfield — Em Cobrança'!W4:W6696,"📋 Proposta Enviada",'Greenfield — Em Cobrança'!H4:H6696) -> 0 | F6: =SUMIF('Greenfield — Em Cobrança'!W4:W6696,"✅ Emissão",'Greenfield — Em Cobrança'!H4:H6696) -> 0 | G6: =SUMIF('Greenfield — Em Cobrança'!W4:W6696,"❌ Perdido",'Greenfield — Em Cobrança'!H4:H6696) -> 0 | H6: =IF(B6=0,"-",F6/B6) -> 0
A8: 📈 FUNIL POR ESTÁGIO | E8: 📅 FOLLOW-UP STATUS
A9: Estágio | B9: Qtd Empresas | C9: Valor Pipeline (R$) | E9: Status | F9: Qtd | G9: % do Total
A10: (Sem estágio) | B10: =COUNTIF('Greenfield — Em Cobrança'!W4:W6696,"") -> 6692 | C10: =SUMIF('Greenfield — Em Cobrança'!W4:W6696,"",'Greenfield — Em Cobrança'!H4:H6696) -> 47634508108 | E10: 🟢 Em dia | F10: =COUNTIF('Greenfield — Em Cobrança'!AB4:AB6696,"*Em dia*") -> 0 | G10: =IF(SUM(G10:G13)=0,"-",F10/SUM(F10:F13)) -> #REF!
A11: 🆕 Novo | B11: =COUNTIF('Greenfield — Em Cobrança'!W4:W6696,"🆕 Novo") -> 1 | C11: =SUMIF('Greenfield — Em Cobrança'!W4:W6696,"🆕 Novo",'Greenfield — Em Cobrança'!H4:H6696) -> 75813202 | E11: 🟡 Atenção | F11: =COUNTIF('Greenfield — Em Cobrança'!AB4:AB6696,"*Atenção*") -> 0 | G11: =IF(SUM(G10:G13)=0,"-",F11/SUM(F10:F13)) -> #REF!
A12: 📞 Consulta Cia | B12: =COUNTIF('Greenfield — Em Cobrança'!W4:W6696,"📞 Consulta Cia") -> 0 | C12: =SUMIF('Greenfield — Em Cobrança'!W4:W6696,"📞 Consulta Cia",'Greenfield — Em Cobrança'!H4:H6696) -> 0 | E12: 🔴 Atrasado | F12: =COUNTIF('Greenfield — Em Cobrança'!AB4:AB6696,"*Atrasado*") -> 1 | G12: =IF(SUM(G10:G13)=0,"-",F12/SUM(F10:F13)) -> #REF!
A13: 📋 Proposta Enviada | B13: =COUNTIF('Greenfield — Em Cobrança'!W4:W6696,"📋 Proposta Enviada") -> 0 | C13: =SUMIF('Greenfield — Em Cobrança'!W4:W6696,"📋 Proposta Enviada",'Greenfield — Em Cobrança'!H4:H6696) -> 0 | E13: Sem contato | F13: =COUNTIF('Greenfield — Em Cobrança'!AB4:AB6696,"") -> 6692 | G13: =IF(SUM(G10:G13)=0,"-",F13/SUM(F10:F13)) -> #REF!
A14: 🤝 Negociação | B14: =COUNTIF('Greenfield — Em Cobrança'!W4:W6696,"🤝 Negociação") -> 0 | C14: =SUMIF('Greenfield — Em Cobrança'!W4:W6696,"🤝 Negociação",'Greenfield — Em Cobrança'!H4:H6696) -> 0
A15: ✅ Emissão | B15: =COUNTIF('Greenfield — Em Cobrança'!W4:W6696,"✅ Emissão") -> 0 | C15: =SUMIF('Greenfield — Em Cobrança'!W4:W6696,"✅ Emissão",'Greenfield — Em Cobrança'!H4:H6696) -> 0
A16: ❌ Perdido | B16: =COUNTIF('Greenfield — Em Cobrança'!W4:W6696,"❌ Perdido") -> 0 | C16: =SUMIF('Greenfield — Em Cobrança'!W4:W6696,"❌ Perdido",'Greenfield — Em Cobrança'!H4:H6696) -> 0
A17: 🗑️ Descarte | B17: =COUNTIF('Greenfield — Em Cobrança'!W4:W6696,"🗑️ Descarte") -> 0 | C17: =SUMIF('Greenfield — Em Cobrança'!W4:W6696,"🗑️ Descarte",'Greenfield — Em Cobrança'!H4:H6696) -> 0
A19: 🏦 RESULTADO SEGURADORA | E19: 💰 PRÊMIO & RECEITA ESTIMADA
A20: Situação Cia | B20: Qtd | C20: Valor (R$) | E20: Métrica | F20: Valor | G20: Obs.
A21: Cadastrou (✅) | B21: =COUNTIF('Greenfield — Em Cobrança'!S4:S6696,"Cadastrou") -> 1 | C21: =SUMIF('Greenfield — Em Cobrança'!S4:S6696,"Cadastrou",'Greenfield — Em Cobrança'!H4:H6696) -> 75813202 | E21: Prêmio Total Estimado (R$) | F21: =SUMIF('Greenfield — Em Cobrança'!AC4:AC6696,">0",'Greenfield — Em Cobrança'!AD4:AD6696) -> 265346.21 | G21: Soma de todos com taxa preenchida
A22: Fora da Política | B22: =COUNTIF('Greenfield — Em Cobrança'!S4:S6696,"Fora da Política") -> 0 | C22: =SUMIF('Greenfield — Em Cobrança'!S4:S6696,"Fora da Política",'Greenfield — Em Cobrança'!H4:H6696) -> 0 | E22: Prêmio Médio por Apólice (R$) | F22: =IF(COUNTIF('Greenfield — Em Cobrança'!AC4:AC6696,">0")=0,"-",F21/COUNTIF('Greenfield — Em Cobrança'!AC4:AC6696,">0")) -> 265346.21 | G22: Média
A23: SERASA | B23: =COUNTIF('Greenfield — Em Cobrança'!S4:S6696,"SERASA") -> 0 | C23: =SUMIF('Greenfield — Em Cobrança'!S4:S6696,"SERASA",'Greenfield — Em Cobrança'!H4:H6696) -> 0 | E23: Qtd com Taxa Preenchida | F23: =COUNTIF('Greenfield — Em Cobrança'!AC4:AC6696,">0") -> 1 | G23: Empresas cotadas
A24: Outro Corretor | B24: =COUNTIF('Greenfield — Em Cobrança'!S4:S6696,"Outro Corretor") -> 0 | C24: =SUMIF('Greenfield — Em Cobrança'!S4:S6696,"Outro Corretor",'Greenfield — Em Cobrança'!H4:H6696) -> 0 | E24: Valor IS Coberto (R$) | F24: =SUMIF('Greenfield — Em Cobrança'!S4:S6696,"Cadastrou",'Greenfield — Em Cobrança'!H4:H6696) -> 75813202 | G24: Valor com seguro aprovado
A25: Inapta/Baixada | B25: =COUNTIF('Greenfield — Em Cobrança'!S4:S6696,"Inapta/Baixada") -> 6 | C25: =SUMIF('Greenfield — Em Cobrança'!S4:S6696,"Inapta/Baixada",'Greenfield — Em Cobrança'!H4:H6696) -> 3.0646608e+08 | E25: Receita V&F Potencial (5a) | F25: =SUM('Greenfield — Em Cobrança'!AI4:AI6696) -> 5.3628624e+08 | G25: Base total × Taxa × 5a × 30%
A26: Pendente consulta | B26: =COUNTIF('Greenfield — Em Cobrança'!S4:S6696,"") -> 6686 | C26: =SUMIF('Greenfield — Em Cobrança'!S4:S6696,"",'Greenfield — Em Cobrança'!H4:H6696) -> 47328042026 | E26: Prêmio Total Apólices (5a) | F26: =SUM('Greenfield — Em Cobrança'!AH4:AH6696) -> 1787620785 | G26: Mercado total endereçável
A28: 🎯 PIPELINE POR PRIORIDADE
A29: Prioridade | B29: Qtd Total | C29: Em Pipeline | D29: Valor Pipeline (R$)
A30: 🔴 ALTA | B30: =COUNTIF('Greenfield — Em Cobrança'!F4:F6696,"*ALTA*") -> 1993 | C30: =COUNTIFS('Greenfield — Em Cobrança'!F4:F6696,"*ALTA*",'Greenfield — Em Cobrança'!W4:W6696,"<>",'Greenfield — Em Cobrança'!W4:W6696,"<>🗑️ Descarte",'Greenfield — Em Cobrança'!W4:W6696,"<>❌ Perdido") -> 1 | D30: {=SUMPRODUCT(ISNUMBER(SEARCH("ALTA",'Greenfield — Em Cobrança'!F4:F6696))*('Greenfield — Em Cobrança'!W4:W6696<>"")*('Greenfield — Em Cobrança'!W4:W6696<>"🗑️ Descarte")*('Greenfield — Em Cobrança'!W4:W6696<>"❌ Perdido")*'Greenfield — Em Cobrança'!H4:H6696)} -> 75813202
A31: 🟡 MÉDIA | B31: =COUNTIF('Greenfield — Em Cobrança'!F4:F6696,"*MÉDIA*") -> 2069 | C31: =COUNTIFS('Greenfield — Em Cobrança'!F4:F6696,"*MÉDIA*",'Greenfield — Em Cobrança'!W4:W6696,"<>",'Greenfield — Em Cobrança'!W4:W6696,"<>🗑️ Descarte",'Greenfield — Em Cobrança'!W4:W6696,"<>❌ Perdido") -> 0 | D31: {=SUMPRODUCT(ISNUMBER(SEARCH("MÉDIA",'Greenfield — Em Cobrança'!F4:F6696))*('Greenfield — Em Cobrança'!W4:W6696<>"")*('Greenfield — Em Cobrança'!W4:W6696<>"🗑️ Descarte")*('Greenfield — Em Cobrança'!W4:W6696<>"❌ Perdido")*'Greenfield — Em Cobrança'!H4:H6696)} -> 0
A32: ⚪ NORMAL | B32: =COUNTIF('Greenfield — Em Cobrança'!F4:F6696,"*NORMAL*") -> 2631 | C32: =COUNTIFS('Greenfield — Em Cobrança'!F4:F6696,"*NORMAL*",'Greenfield — Em Cobrança'!W4:W6696,"<>",'Greenfield — Em Cobrança'!W4:W6696,"<>🗑️ Descarte",'Greenfield — Em Cobrança'!W4:W6696,"<>❌ Perdido") -> 0 | D32: {=SUMPRODUCT(ISNUMBER(SEARCH("NORMAL",'Greenfield — Em Cobrança'!F4:F6696))*('Greenfield — Em Cobrança'!W4:W6696<>"")*('Greenfield — Em Cobrança'!W4:W6696<>"🗑️ Descarte")*('Greenfield — Em Cobrança'!W4:W6696<>"❌ Perdido")*'Greenfield — Em Cobrança'!H4:H6696)} -> 0
A33: TOTAL | B33: =SUM(B30:B32) -> 6693 | C33: =SUM(C30:C32) -> 1 | D33: =SUM(D30:D32) -> 75813202

Sheet Greenfield — Em Cobrança
A1: V&F | Seguro Garantia — Greenfield: Inscrições Ajuizadas sem Garantia (R$1M–R$50M | 2021–2025) | BA1: Situação | BB1: Col1_Default | BC1: Col2_Default | BD1: Col3_Default
A2: Base: 6,693 empresas | 1993 ALTA | 2069 MÉDIA | 2631 NORMAL • Apenas PRINCIPAL • Sem falidos/RJ • CNPJ Raiz | S2: ✏️ = campo editável | 🔒 = protegido (fórmula ou dado-fonte) | BA2: Cadastrou | BB2: — | BC2: — | BD2: ✅ Aprovado
A3: # | B3: Empresa | C3: UF | D3: CNPJ Raiz | E3: Score | F3: Prioridade | G3: Faixa Valor | H3: Valor Aberto (R$) | I3: Qtd. Inscrições | J3: Anos na PGFN | K3: Ano Últ. Inscrição | L3: Receita Principal | M3: Ano Entrada PGFN | N3: Situações Presentes | O3: Base12 | P3: DV1 | Q3: DV2 | R3: CNPJ Completo | S3: ✏️ Situação Cia | T3: ✏️ Limite / Status | U3: ✏️ Taxa / Motivo | V3: Resultado / Ação | W3: ✏️ Estágio Pipeline | X3: ✏️ Responsável V&F | Y3: ✏️ Dt. Último Contato | Z3: ✏️ Próx. Follow-up | AA3: Dias s/ Contato | AB3: Status Follow-up | AC3: ✏️ Taxa Real (%) | AD3: Prêmio Estim. (R$) | AE3: ✏️ Observações | AF3: Taxa Aplicada | AG3: Prêmio Anual (R$) | AH3: AI3 | AI3: Receita V&F 30% (R$) | AJ3: ✏️ Capital Social (R$) | AK3: ✏️ Porte | AL3: ✏️ Simples Nacional | AM3: ✏️ Telefone | AN3: ✏️ E-mail | AO3: ✏️ Contato (Nome) | AP3: ✏️ Contato (Cargo) | AQ3: ✏️ Contato (Celular) | BA3: Fora da Política | BC3: Regra da Cia | BD3: Refazer 2ª Cia
A4: 1 | B4: MANTOVANI INTERNATIONAL TRADING S.A. | C4: SP | D4: 40008207 | E4: 70.37 | F4: 🔴 ALTA | G4: R$ 50M+ | H4: 75813202 | I4: 2 | J4: 0.7 | K4: 2025 | L4: Receita da dívida ativa - CSLL | Receita da dívida ativa - IRPJ | M4: 2025 | N4: COBRANCA | O4: =TEXT(D4,"00000000")&"0001" -> 400082070001 | P4: =IF(MOD(MID(O4,1,1)*5+MID(O4,2,1)*4+MID(O4,3,1)*3+MID(O4,4,1)*2+MID(O4,5,1)*9+MID(O4,6,1)*8+MID(O4,7,1)*7+MID(O4,8,1)*6+MID(O4,9,1)*5+MID(O4,10,1)*4+MID(O4,11,1)*3+MID(O4,12,1)*2,11)<2,0,11-MOD(MID(O4,1,1)*5+MID(O4,2,1)*4+MID(O4,3,1)*3+MID(O4,4,1)*2+MID(O4,5,1)*9+MID(O4,6,1)*8+MID(O4,7,1)*7+MID(O4,8,1)*6+MID(O4,9,1)*5+MID(O4,10,1)*4+MID(O4,11,1)*3+MID(O4,12,1)*2,11)) -> 2 | Q4: =IF(MOD(MID(O4,1,1)*6+MID(O4,2,1)*5+MID(O4,3,1)*4+MID(O4,4,1)*3+MID(O4,5,1)*2+MID(O4,6,1)*9+MID(O4,7,1)*8+MID(O4,8,1)*7+MID(O4,9,1)*6+MID(O4,10,1)*5+MID(O4,11,1)*4+MID(O4,12,1)*3+P4*2,11)<2,0,11-MOD(MID(O4,1,1)*6+MID(O4,2,1)*5+MID(O4,3,1)*4+MID(O4,4,1)*3+MID(O4,5,1)*2+MID(O4,6,1)*9+MID(O4,7,1)*8+MID(O4,8,1)*7+MID(O4,9,1)*6+MID(O4,10,1)*5+MID(O4,11,1)*4+MID(O4,12,1)*3+P4*2,11)) -> 7 | R4: =MID(O4,1,2)&"."&MID(O4,3,3)&"."&MID(O4,6,3)&"/"&MID(O4,9,4)&"-"&TEXT(P4,"0")&TEXT(Q4,"0") -> 40.008.207/0001-27 | S4: Cadastrou | T4: 100000000 | U4: 0.35 | V4: =IF(S4="","",XLOOKUP(S4,$BA$2:$BA$6,$BD$2:$BD$6,"")) -> ✅ Aprovado | W4: 🆕 Novo | X4: Rodrigo Vazquez | Y4: 46106 | Z4: 46107 | AA4: =IF(Y4="","",IF(INT(TODAY()-Y4)<0,"⚠️ Data futura",INT(TODAY()-Y4))) -> 6 | AB4: =IF(AA4="","",IF(Z4="",IF(AA4>14,"🔴 Atrasado",IF(AA4>7,"🟡 Atenção","🟢 Em dia")),IF(TODAY()>Z4,"🔴 Atrasado",IF(Z4-TODAY()<=3,"🟡 Atenção","🟢 Em dia")))) -> 🔴 Atrasado | AC4: 0.0035 | AD4: =IF(OR(AC4="",H4=""),"",H4*AC4) -> 265346.21 | AE4: Falta CCG | AF4: =IF(AC4>0,AC4,'⚙️ Config'!$B$10) -> 0.0035 | AG4: =H4*AF4 -> 265346.21 | AH4: =AG4*'⚙️ Config'!$B$11 -> 1326731 | AI4: =AH4*'⚙️ Config'!$B$12 -> 398019.31 | AJ4: 150000000 | AK4: Grande | AL4: Não | AM4: 11 4758-2949 | AN4: karinamantovani@gmail.com | BA4: SERASA | BC4: SERASA | BD4: Análise Manual
A5: 2 | B5: MEAT & LEATHER INDUSTRIA E COMERCIO DE ALIMENTOS LTDA | C5: MS | D5: 30735239 | E5: 58.37 | F5: 🔴 ALTA | G5: R$ 50M+ | H5: 63544701 | I5: 2 | J5: 1 | K5: 2025 | L5: Receita da dívida ativa - CSLL | Receita da dívida ativa - IRPJ | M5: 2025 | N5: COBRANCA | O5: =TEXT(D5,"00000000")&"0001" -> 307352390001 | P5: =IF(MOD(MID(O5,1,1)*5+MID(O5,2,1)*4+MID(O5,3,1)*3+MID(O5,4,1)*2+MID(O5,5,1)*9+MID(O5,6,1)*8+MID(O5,7,1)*7+MID(O5,8,1)*6+MID(O5,9,1)*5+MID(O5,10,1)*4+MID(O5,11,1)*3+MID(O5,12,1)*2,11)<2,0,11-MOD(MID(O5,1,1)*5+MID(O5,2,1)*4+MID(O5,3,1)*3+MID(O5,4,1)*2+MID(O5,5,1)*9+MID(O5,6,1)*8+MID(O5,7,1)*7+MID(O5,8,1)*6+MID(O5,9,1)*5+MID(O5,10,1)*4+MID(O5,11,1)*3+MID(O5,12,1)*2,11)) -> 7 | Q5: =IF(MOD(MID(O5,1,1)*6+MID(O5,2,1)*5+MID(O5,3,1)*4+MID(O5,4,1)*3+MID(O5,5,1)*2+MID(O5,6,1)*9+MID(O5,7,1)*8+MID(O5,8,1)*7+MID(O5,9,1)*6+MID(O5,10,1)*5+MID(O5,11,1)*4+MID(O5,12,1)*3+P5*2,11)<2,0,11-MOD(MID(O5,1,1)*6+MID(O5,2,1)*5+MID(O5,3,1)*4+MID(O5,4,1)*3+MID(O5,5,1)*2+MID(O5,6,1)*9+MID(O5,7,1)*8+MID(O5,8,1)*7+MID(O5,9,1)*6+MID(O5,10,1)*5+MID(O5,11,1)*4+MID(O5,12,1)*3+P5*2,11)) -> 0 | R5: =MID(O5,1,2)&"."&MID(O5,3,3)&"."&MID(O5,6,3)&"/"&MID(O5,9,4)&"-"&TEXT(P5,"0")&TEXT(Q5,"0") -> 30.735.239/0001-70 | S5: Inapta/Baixada | T5: =IF(S5="","",IF(S5="Cadastrou","",XLOOKUP(S5,$BA$2:$BA$6,$BB$2:$BB$6,""))) | U5: =IF(S5="","",IF(S5="Cadastrou","",XLOOKUP(S5,$BA$2:$BA$6,$BC$2:$BC$6,""))) | V5: =IF(S5="","",XLOOKUP(S5,$BA$2:$BA$6,$BD$2:$BD$6,"")) | AA5: =IF(Y5="","",IF(INT(TODAY()-Y5)<0,"⚠️ Data futura",INT(TODAY()-Y5))) | AB5: =IF(AA5="","",IF(Z5="",IF(AA5>14,"🔴 Atrasado",IF(AA5>7,"🟡 Atenção","🟢 Em dia")),IF(TODAY()>Z5,"🔴 Atrasado",IF(Z5-TODAY()<=3,"🟡 Atenção","🟢 Em dia")))) | AD5: =IF(OR(AC5="",H5=""),"",H5*AC5) | AF5: =IF(AC5>0,AC5,'⚙️ Config'!$B$10) -> 0.0075 | AG5: =H5*AF5 -> 476585.26 | AH5: =AG5*'⚙️ Config'!$B$11 -> 2382926.3 | AI5: =AH5*'⚙️ Config'!$B$12 -> 714877.89 | BA5: Outro Corretor | BC5: Análise | BD5: Ana
A6: 3 | B6: HMAR CONSULTORIA EM INFORMATICA LTDA | C6: SP | D6: 09182880 | E6: 67.34 | F6: 🔴 ALTA | G6: R$ 50M+ | H6: 58517893 | I6: 2 | J6: 0.8 | K6: 2025 | L6: Receita da dívida ativa - IOF | Receita da dívida ativa - IRRF | M6: 2025 | N6: AJUIZADA_SEM_GAR | O6: =TEXT(D6,"00000000")&"0001" -> 091828800001 | P6: =IF(MOD(MID(O6,1,1)*5+MID(O6,2,1)*4+MID(O6,3,1)*3+MID(O6,4,1)*2+MID(O6,5,1)*9+MID(O6,6,1)*8+MID(O6,7,1)*7+MID(O6,8,1)*6+MID(O6,9,1)*5+MID(O6,10,1)*4+MID(O6,11,1)*3+MID(O6,12,1)*2,11)<2,0,11-MOD(MID(O6,1,1)*5+MID(O6,2,1)*4+MID(O6,3,1)*3+MID(O6,4,1)*2+MID(O6,5,1)*9+MID(O6,6,1)*8+MID(O6,7,1)*7+MID(O6,8,1)*6+MID(O6,9,1)*5+MID(O6,10,1)*4+MID(O6,11,1)*3+MID(O6,12,1)*2,11)) -> 3 | Q6: =IF(MOD(MID(O6,1,1)*6+MID(O6,2,1)*5+MID(O6,3,1)*4+MID(O6,4,1)*3+MID(O6,5,1)*2+MID(O6,6,1)*9+MID(O6,7,1)*8+MID(O6,8,1)*7+MID(O6,9,1)*6+MID(O6,10,1)*5+MID(O6,11,1)*4+MID(O6,12,1)*3+P6*2,11)<2,0,11-MOD(MID(O6,1,1)*6+MID(O6,2,1)*5+MID(O6,3,1)*4+MID(O6,4,1)*3+MID(O6,5,1)*2+MID(O6,6,1)*9+MID(O6,7,1)*8+MID(O6,8,1)*7+MID(O6,9,1)*6+MID(O6,10,1)*5+MID(O6,11,1)*4+MID(O6,12,1)*3+P6*2,11)) -> 9 | R6: =MID(O6,1,2)&"."&MID(O6,3,3)&"."&MID(O6,6,3)&"/"&MID(O6,9,4)&"-"&TEXT(P6,"0")&TEXT(Q6,"0") -> 09.182.880/0001-39 | S6: Inapta/Baixada | T6: =IF(S6="","",IF(S6="Cadastrou","",XLOOKUP(S6,$BA$2:$BA$6,$BB$2:$BB$6,""))) | U6: =IF(S6="","",IF(S6="Cadastrou","",XLOOKUP(S6,$BA$2:$BA$6,$BC$2:$BC$6,""))) | V6: =IF(S6="","",XLOOKUP(S6,$BA$2:$BA$6,$BD$2:$BD$6,"")) | AA6: =IF(Y6="","",IF(INT(TODAY()-Y6)<0,"⚠️ Data futura",INT(TODAY()-Y6))) | AB6: =IF(AA6="","",IF(Z6="",IF(AA6>14,"🔴 Atrasado",IF(AA6>7,"🟡 Atenção","🟢 Em dia")),IF(TODAY()>Z6,"🔴 Atrasado",IF(Z6-TODAY()<=3,"🟡 Atenção","🟢 Em dia")))) | AD6: =IF(OR(AC6="",H6=""),"",H6*AC6) | AF6: =IF(AC6>0,AC6,'⚙️ Config'!$B$10) -> 0.0075 | AG6: =H6*AF6 -> 438884.2 | AH6: =AG6*'⚙️ Config'!$B$11 -> 2194421 | AI6: =AH6*'⚙️ Config'!$B$12 -> 658326.3 | BC6: Descarte | BD6: Descarte
A7: 4 | B7: MUNICIPIO DE CACHOEIRA PAULISTA | C7: SP | D7: 45192275 | E7: 59.53 | F7: 🔴 ALTA | G7: R$ 50M+ | H7: 53460614 | I7: 2 | J7: 1 | K7: 2025 | L7: R D Ativa -Multa Isolada Compensação Previdenciária Indevida | R D Ativa - Glosa de Compensação Previdenciária | M7: 2025 | N7: AJUIZADA_SEM_GAR | O7: =TEXT(D7,"00000000")&"0001" -> 451922750001 | P7: =IF(MOD(MID(O7,1,1)*5+MID(O7,2,1)*4+MID(O7,3,1)*3+MID(O7,4,1)*2+MID(O7,5,1)*9+MID(O7,6,1)*8+MID(O7,7,1)*7+MID(O7,8,1)*6+MID(O7,9,1)*5+MID(O7,10,1)*4+MID(O7,11,1)*3+MID(O7,12,1)*2,11)<2,0,11-MOD(MID(O7,1,1)*5+MID(O7,2,1)*4+MID(O7,3,1)*3+MID(O7,4,1)*2+MID(O7,5,1)*9+MID(O7,6,1)*8+MID(O7,7,1)*7+MID(O7,8,1)*6+MID(O7,9,1)*5+MID(O7,10,1)*4+MID(O7,11,1)*3+MID(O7,12,1)*2,11)) -> 0 | Q7: =IF(MOD(MID(O7,1,1)*6+MID(O7,2,1)*5+MID(O7,3,1)*4+MID(O7,4,1)*3+MID(O7,5,1)*2+MID(O7,6,1)*9+MID(O7,7,1)*8+MID(O7,8,1)*7+MID(O7,9,1)*6+MID(O7,10,1)*5+MID(O7,11,1)*4+MID(O7,12,1)*3+P7*2,11)<2,0,11-MOD(MID(O7,1,1)*6+MID(O7,2,1)*5+MID(O7,3,1)*4+MID(O7,4,1)*3+MID(O7,5,1)*2+MID(O7,6,1)*9+MID(O7,7,1)*8+MID(O7,8,1)*7+MID(O7,9,1)*6+MID(O7,10,1)*5+MID(O7,11,1)*4+MID(O7,12,1)*3+P7*2,11)) -> 2 | R7: =MID(O7,1,2)&"."&MID(O7,3,3)&"."&MID(O7,6,3)&"/"&MID(O7,9,4)&"-"&TEXT(P7,"0")&TEXT(Q7,"0") -> 45.192.275/0001-02 | S7: Inapta/Baixada | T7: =IF(S7="","",IF(S7="Cadastrou","",XLOOKUP(S7,$BA$2:$BA$6,$BB$2:$BB$6,""))) | U7: =IF(S7="","",IF(S7="Cadastrou","",XLOOKUP(S7,$BA$2:$BA$6,$BC$2:$BC$6,""))) | V7: =IF(S7="","",XLOOKUP(S7,$BA$2:$BA$6,$BD$2:$BD$6,"")) | AA7: =IF(Y7="","",IF(INT(TODAY()-Y7)<0,"⚠️ Data futura",INT(TODAY()-Y7))) | AB7: =IF(AA7="","",IF(Z7="",IF(AA7>14,"🔴 Atrasado",IF(AA7>7,"🟡 Atenção","🟢 Em dia")),IF(TODAY()>Z7,"🔴 Atrasado",IF(Z7-TODAY()<=3,"🟡 Atenção","🟢 Em dia")))) | AD7: =IF(OR(AC7="",H7=""),"",H7*AC7) | AF7: =IF(AC7>0,AC7,'⚙️ Config'!$B$10) -> 0.0075 | AG7: =H7*AF7 -> 400954.61 | AH7: =AG7*'⚙️ Config'!$B$11 -> 2004773 | AI7: =AH7*'⚙️ Config'!$B$12 -> 601431.91
A8: 5 | B8: COPAR CONDUTORES ELETRICOS LTDA | C8: SP | D8: 17344440 | E8: 41.86 | F8: 🔴 ALTA | G8: R$ 50M+ | H8: 52937645 | I8: 2 | J8: 1.8 | K8: 2024 | L8: Receita da dívida ativa - PIS | Receita da dívida ativa - CSLL | M8: 2024 | N8: COBRANCA | O8: =TEXT(D8,"00000000")&"0001" -> 173444400001 | P8: =IF(MOD(MID(O8,1,1)*5+MID(O8,2,1)*4+MID(O8,3,1)*3+MID(O8,4,1)*2+MID(O8,5,1)*9+MID(O8,6,1)*8+MID(O8,7,1)*7+MID(O8,8,1)*6+MID(O8,9,1)*5+MID(O8,10,1)*4+MID(O8,11,1)*3+MID(O8,12,1)*2,11)<2,0,11-MOD(MID(O8,1,1)*5+MID(O8,2,1)*4+MID(O8,3,1)*3+MID(O8,4,1)*2+MID(O8,5,1)*9+MID(O8,6,1)*8+MID(O8,7,1)*7+MID(O8,8,1)*6+MID(O8,9,1)*5+MID(O8,10,1)*4+MID(O8,11,1)*3+MID(O8,12,1)*2,11)) -> 6 | Q8: =IF(MOD(MID(O8,1,1)*6+MID(O8,2,1)*5+MID(O8,3,1)*4+MID(O8,4,1)*3+MID(O8,5,1)*2+MID(O8,6,1)*9+MID(O8,7,1)*8+MID(O8,8,1)*7+MID(O8,9,1)*6+MID(O8,10,1)*5+MID(O8,11,1)*4+MID(O8,12,1)*3+P8*2,11)<2,0,11-MOD(MID(O8,1,1)*6+MID(O8,2,1)*5+MID(O8,3,1)*4+MID(O8,4,1)*3+MID(O8,5,1)*2+MID(O8,6,1)*9+MID(O8,7,1)*8+MID(O8,8,1)*7+MID(O8,9,1)*6+MID(O8,10,1)*5+MID(O8,11,1)*4+MID(O8,12,1)*3+P8*2,11)) -> 9 | R8: =MID(O8,1,2)&"."&MID(O8,3,3)&"."&MID(O8,6,3)&"/"&MID(O8,9,4)&"-"&TEXT(P8,"0")&TEXT(Q8,"0") -> 17.344.440/0001-69 | S8: Inapta/Baixada | T8: =IF(S8="","",IF(S8="Cadastrou","",XLOOKUP(S8,$BA$2:$BA$6,$BB$2:$BB$6,""))) | U8: =IF(S8="","",IF(S8="Cadastrou","",XLOOKUP(S8,$BA$2:$BA$6,$BC$2:$BC$6,""))) | V8: =IF(S8="","",XLOOKUP(S8,$BA$2:$BA$6,$BD$2:$BD$6,"")) | AA8: =IF(Y8="","",IF(INT(TODAY()-Y8)<0,"⚠️ Data futura",INT(TODAY()-Y8))) | AB8: =IF(AA8="","",IF(Z8="",IF(AA8>14,"🔴 Atrasado",IF(AA8>7,"🟡 Atenção","🟢 Em dia")),IF(TODAY()>Z8,"🔴 Atrasado",IF(Z8-TODAY()<=3,"🟡 Atenção","🟢 Em dia")))) | AD8: =IF(OR(AC8="",H8=""),"",H8*AC8) | AF8: =IF(AC8>0,AC8,'⚙️ Config'!$B$10) -> 0.0075 | AG8: =H8*AF8 -> 397032.34 | AH8: =AG8*'⚙️ Config'!$B$11 -> 1985161.7 | AI8: =AH8*'⚙️ Config'!$B$12 -> 595548.51
A9: 6 | B9: ACO E ACO VERGALHOES LTDA | C9: MS | D9: 08345565 | E9: 65.23 | F9: 🔴 ALTA | G9: R$ 50M+ | H9: 51488054 | I9: 2 | J9: 0.8 | K9: 2025 | L9: Receita da dívida ativa - CSLL | Receita da dívida ativa - IRPJ | M9: 2025 | N9: AJUIZADA_SEM_GAR | O9: =TEXT(D9,"00000000")&"0001" -> 083455650001 | P9: =IF(MOD(MID(O9,1,1)*5+MID(O9,2,1)*4+MID(O9,3,1)*3+MID(O9,4,1)*2+MID(O9,5,1)*9+MID(O9,6,1)*8+MID(O9,7,1)*7+MID(O9,8,1)*6+MID(O9,9,1)*5+MID(O9,10,1)*4+MID(O9,11,1)*3+MID(O9,12,1)*2,11)<2,0,11-MOD(MID(O9,1,1)*5+MID(O9,2,1)*4+MID(O9,3,1)*3+MID(O9,4,1)*2+MID(O9,5,1)*9+MID(O9,6,1)*8+MID(O9,7,1)*7+MID(O9,8,1)*6+MID(O9,9,1)*5+MID(O9,10,1)*4+MID(O9,11,1)*3+MID(O9,12,1)*2,11)) -> 1 | Q9: =IF(MOD(MID(O9,1,1)*6+MID(O9,2,1)*5+MID(O9,3,1)*4+MID(O9,4,1)*3+MID(O9,5,1)*2+MID(O9,6,1)*9+MID(O9,7,1)*8+MID(O9,8,1)*7+MID(O9,9,1)*6+MID(O9,10,1)*5+MID(O9,11,1)*4+MID(O9,12,1)*3+P9*2,11)<2,0,11-MOD(MID(O9,1,1)*6+MID(O9,2,1)*5+MID(O9,3,1)*4+MID(O9,4,1)*3+MID(O9,5,1)*2+MID(O9,6,1)*9+MID(O9,7,1)*8+MID(O9,8,1)*7+MID(O9,9,1)*6+MID(O9,10,1)*5+MID(O9,11,1)*4+MID(O9,12,1)*3+P9*2,11)) -> 2 | R9: =MID(O9,1,2)&"."&MID(O9,3,3)&"."&MID(O9,6,3)&"/"&MID(O9,9,4)&"-"&TEXT(P9,"0")&TEXT(Q9,"0") -> 08.345.565/0001-12 | T9: =IF(S9="","",IF(S9="Cadastrou","",XLOOKUP(S9,$BA$2:$BA$6,$BB$2:$BB$6,""))) | U9: =IF(S9="","",IF(S9="Cadastrou","",XLOOKUP(S9,$BA$2:$BA$6,$BC$2:$BC$6,""))) | V9: =IF(S9="","",XLOOKUP(S9,$BA$2:$BA$6,$BD$2:$BD$6,"")) | AA9: =IF(Y9="","",IF(INT(TODAY()-Y9)<0,"⚠️ Data futura",INT(TODAY()-Y9))) | AB9: =IF(AA9="","",IF(Z9="",IF(AA9>14,"🔴 Atrasado",IF(AA9>7,"🟡 Atenção","🟢 Em dia")),IF(TODAY()>Z9,"🔴 Atrasado",IF(Z9-TODAY()<=3,"🟡 Atenção","🟢 Em dia")))) | AD9: =IF(OR(AC9="",H9=""),"",H9*AC9) | AF9: =IF(AC9>0,AC9,'⚙️ Config'!$B$10) -> 0.0075 | AG9: =H9*AF9 -> 386160.41 | AH9: =AG9*'⚙️ Config'!$B$11 -> 1930802 | AI9: =AH9*'⚙️ Config'!$B$12 -> 579240.61
A10: 7 | B10: FRIG WEST TRANSPORTES LTDA | C10: SP | D10: 10426902 | E10: 50.08 | F10: 🔴 ALTA | G10: R$ 30-50M | H10: 44306739 | I10: 2 | J10: 1.3 | K10: 2024 | L10: R D Ativa - Contribuição Previdenciária Sobre Receita Bruta | R D Ativa - Contribuição Risco Ambiental/Aposent Especial | M10: 2024 | N10: COBRANCA | O10: =TEXT(D10,"00000000")&"0001" -> 104269020001 | P10: =IF(MOD(MID(O10,1,1)*5+MID(O10,2,1)*4+MID(O10,3,1)*3+MID(O10,4,1)*2+MID(O10,5,1)*9+MID(O10,6,1)*8+MID(O10,7,1)*7+MID(O10,8,1)*6+MID(O10,9,1)*5+MID(O10,10,1)*4+MID(O10,11,1)*3+MID(O10,12,1)*2,11)<2,0,11-MOD(MID(O10,1,1)*5+MID(O10,2,1)*4+MID(O10,3,1)*3+MID(O10,4,1)*2+MID(O10,5,1)*9+MID(O10,6,1)*8+MID(O10,7,1)*7+MID(O10,8,1)*6+MID(O10,9,1)*5+MID(O10,10,1)*4+MID(O10,11,1)*3+MID(O10,12,1)*2,11)) -> 4 | Q10: =IF(MOD(MID(O10,1,1)*6+MID(O10,2,1)*5+MID(O10,3,1)*4+MID(O10,4,1)*3+MID(O10,5,1)*2+MID(O10,6,1)*9+MID(O10,7,1)*8+MID(O10,8,1)*7+MID(O10,9,1)*6+MID(O10,10,1)*5+MID(O10,11,1)*4+MID(O10,12,1)*3+P10*2,11)<2,0,11-MOD(MID(O10,1,1)*6+MID(O10,2,1)*5+MID(O10,3,1)*4+MID(O10,4,1)*3+MID(O10,5,1)*2+MID(O10,6,1)*9+MID(O10,7,1)*8+MID(O10,8,1)*7+MID(O10,9,1)*6+MID(O10,10,1)*5+MID(O10,11,1)*4+MID(O10,12,1)*3+P10*2,11)) -> 8 | R10: =MID(O10,1,2)&"."&MID(O10,3,3)&"."&MID(O10,6,3)&"/"&MID(O10,9,4)&"-"&TEXT(P10,"0")&TEXT(Q10,"0") -> 10.426.902/0001-48 | T10: =IF(S10="","",IF(S10="Cadastrou","",XLOOKUP(S10,$BA$2:$BA$6,$BB$2:$BB$6,""))) | U10: =IF(S10="","",IF(S10="Cadastrou","",XLOOKUP(S10,$BA$2:$BA$6,$BC$2:$BC$6,""))) | V10: =IF(S10="","",XLOOKUP(S10,$BA$2:$BA$6,$BD$2:$BD$6,"")) | AA10: =IF(Y10="","",IF(INT(TODAY()-Y10)<0,"⚠️ Data futura",INT(TODAY()-Y10))) | AB10: =IF(AA10="","",IF(Z10="",IF(AA10>14,"🔴 Atrasado",IF(AA10>7,"🟡 Atenção","🟢 Em dia")),IF(TODAY()>Z10,"🔴 Atrasado",IF(Z10-TODAY()<=3,"🟡 Atenção","🟢 Em dia")))) | AD10: =IF(OR(AC10="",H10=""),"",H10*AC10) | AF10: =IF(AC10>0,AC10,'⚙️ Config'!$B$10) -> 0.0075 | AG10: =H10*AF10 -> 332300.55 | AH10: =AG10*'⚙️ Config'!$B$11 -> 1661502.7 | AI10: =AH10*'⚙️ Config'!$B$12 -> 498450.82 | AO10: Inapta/Baixada
A11: 8 | B11: YOUNG LINE CONFECCOES LTDA | C11: SP | D11: 96420344 | E11: 56.12 | F11: 🔴 ALTA | G11: R$ 30-50M | H11: 41784265 | I11: 1 | J11: 1.5 | K11: 2024 | L11: Receita da dívida ativa - IRRF | M11: 2024 | N11: COBRANCA | O11: =TEXT(D11,"00000000")&"0001" -> 964203440001 | P11: =IF(MOD(MID(O11,1,1)*5+MID(O11,2,1)*4+MID(O11,3,1)*3+MID(O11,4,1)*2+MID(O11,5,1)*9+MID(O11,6,1)*8+MID(O11,7,1)*7+MID(O11,8,1)*6+MID(O11,9,1)*5+MID(O11,10,1)*4+MID(O11,11,1)*3+MID(O11,12,1)*2,11)<2,0,11-MOD(MID(O11,1,1)*5+MID(O11,2,1)*4+MID(O11,3,1)*3+MID(O11,4,1)*2+MID(O11,5,1)*9+MID(O11,6,1)*8+MID(O11,7,1)*7+MID(O11,8,1)*6+MID(O11,9,1)*5+MID(O11,10,1)*4+MID(O11,11,1)*3+MID(O11,12,1)*2,11)) -> 2 | Q11: =IF(MOD(MID(O11,1,1)*6+MID(O11,2,1)*5+MID(O11,3,1)*4+MID(O11,4,1)*3+MID(O11,5,1)*2+MID(O11,6,1)*9+MID(O11,7,1)*8+MID(O11,8,1)*7+MID(O11,9,1)*6+MID(O11,10,1)*5+MID(O11,11,1)*4+MID(O11,12,1)*3+P11*2,11)<2,0,11-MOD(MID(O11,1,1)*6+MID(O11,2,1)*5+MID(O11,3,1)*4+MID(O11,4,1)*3+MID(O11,5,1)*2+MID(O11,6,1)*9+MID(O11,7,1)*8+MID(O11,8,1)*7+MID(O11,9,1)*6+MID(O11,10,1)*5+MID(O11,11,1)*4+MID(O11,12,1)*3+P11*2,11)) -> 9 | R11: =MID(O11,1,2)&"."&MID(O11,3,3)&"."&MID(O11,6,3)&"/"&MID(O11,9,4)&"-"&TEXT(P11,"0")&TEXT(Q11,"0") -> 96.420.344/0001-29 | S11: Inapta/Baixada | T11: =IF(S11="","",IF(S11="Cadastrou","",XLOOKUP(S11,$BA$2:$BA$6,$BB$2:$BB$6,""))) | U11: =IF(S11="","",IF(S11="Cadastrou","",XLOOKUP(S11,$BA$2:$BA$6,$BC$2:$BC$6,""))) | V11: =IF(S11="","",XLOOKUP(S11,$BA$2:$BA$6,$BD$2:$BD$6,"")) | AA11: =IF(Y11="","",IF(INT(TODAY()-Y11)<0,"⚠️ Data futura",INT(TODAY()-Y11))) | AB11: =IF(AA11="","",IF(Z11="",IF(AA11>14,"🔴 Atrasado",IF(AA11>7,"🟡 Atenção","🟢 Em dia")),IF(TODAY()>Z11,"🔴 Atrasado",IF(Z11-TODAY()<=3,"🟡 Atenção","🟢 Em dia")))) | AD11: =IF(OR(AC11="",H11=""),"",H11*AC11) | AF11: =IF(AC11>0,AC11,'⚙️ Config'!$B$10) -> 0.0075 | AG11: =H11*AF11 -> 313381.99 | AH11: =AG11*'⚙️ Config'!$B$11 -> 1566910 | AI11: =AH11*'⚙️ Config'!$B$12 -> 470072.99
A12: 9 | B12: MADEX INDUSTRIA DE PLASTICOS LTDA | C12: SP | D12: 45067428 | E12: 69.45 | F12: 🔴 ALTA | G12: R$ 30-50M | H12: 41763002 | I12: 2 | J12: 0.7 | K12: 2025 | L12: Receita da dívida ativa - CSLL | Receita da dívida ativa - IRPJ | M12: 2025 | N12: COBRANCA | O12: =TEXT(D12,"00000000")&"0001" -> 450674280001 | P12: =IF(MOD(MID(O12,1,1)*5+MID(O12,2,1)*4+MID(O12,3,1)*3+MID(O12,4,1)*2+MID(O12,5,1)*9+MID(O12,6,1)*8+MID(O12,7,1)*7+MID(O12,8,1)*6+MID(O12,9,1)*5+MID(O12,10,1)*4+MID(O12,11,1)*3+MID(O12,12,1)*2,11)<2,0,11-MOD(MID(O12,1,1)*5+MID(O12,2,1)*4+MID(O12,3,1)*3+MID(O12,4,1)*2+MID(O12,5,1)*9+MID(O12,6,1)*8+MID(O12,7,1)*7+MID(O12,8,1)*6+MID(O12,9,1)*5+MID(O12,10,1)*4+MID(O12,11,1)*3+MID(O12,12,1)*2,11)) -> 9 | Q12: =IF(MOD(MID(O12,1,1)*6+MID(O12,2,1)*5+MID(O12,3,1)*4+MID(O12,4,1)*3+MID(O12,5,1)*2+MID(O12,6,1)*9+MID(O12,7,1)*8+MID(O12,8,1)*7+MID(O12,9,1)*6+MID(O12,10,1)*5+MID(O12,11,1)*4+MID(O12,12,1)*3+P12*2,11)<2,0,11-MOD(MID(O12,1,1)*6+MID(O12,2,1)*5+MID(O12,3,1)*4+MID(O12,4,1)*3+MID(O12,5,1)*2+MID(O12,6,1)*9+MID(O12,7,1)*8+MID(O12,8,1)*7+MID(O12,9,1)*6+MID(O12,10,1)*5+MID(O12,11,1)*4+MID(O12,12,1)*3+P12*2,11)) -> 0 | R12: =MID(O12,1,2)&"."&MID(O12,3,3)&"."&MID(O12,6,3)&"/"&MID(O12,9,4)&"-"&TEXT(P12,"0")&TEXT(Q12,"0") -> 45.067.428/0001-90 | T12: =IF(S12="","",IF(S12="Cadastrou","",XLOOKUP(S12,$BA$2:$BA$6,$BB$2:$BB$6,""))) | U12: =IF(S12="","",IF(S12="Cadastrou","",XLOOKUP(S12,$BA$2:$BA$6,$BC$2:$BC$6,""))) | V12: =IF(S12="","",XLOOKUP(S12,$BA$2:$BA$6,$BD$2:$BD$6,"")) | AA12: =IF(Y12="","",IF(INT(TODAY()-Y12)<0,"⚠️ Data futura",INT(TODAY()-Y12))) | AB12: =IF(AA12="","",IF(Z12="",IF(AA12>14,"🔴 Atrasado",IF(AA12>7,"🟡 Atenção","🟢 Em dia")),IF(TODAY()>Z12,"🔴 Atrasado",IF(Z12-TODAY()<=3,"🟡 Atenção","🟢 Em dia")))) | AD12: =IF(OR(AC12="",H12=""),"",H12*AC12) | AF12: =IF(AC12>0,AC12,'⚙️ Config'!$B$10) -> 0.0075 | AG12: =H12*AF12 -> 313222.52 | AH12: =AG12*'⚙️ Config'!$B$11 -> 1566112.6 | AI12: =AH12*'⚙️ Config'!$B$12 -> 469833.78
A13: 10 | B13: FX VIAGENS E TURISMO LTDA | C13: SP | D13: 10923833 | E13: 45.03 | F13: 🔴 ALTA | G13: R$ 30-50M | H13: 36220964 | I13: 2 | J13: 1.8 | K13: 2024 | L13: Receita da dívida ativa - PIS | R D Ativa - Simples Nacional | M13: 2024 | N13: AJUIZADA_SEM_GAR | O13: =TEXT(D13,"00000000")&"0001" -> 109238330001 | P13: =IF(MOD(MID(O13,1,1)*5+MID(O13,2,1)*4+MID(O13,3,1)*3+MID(O13,4,1)*2+MID(O13,5,1)*9+MID(O13,6,1)*8+MID(O13,7,1)*7+MID(O13,8,1)*6+MID(O13,9,1)*5+MID(O13,10,1)*4+MID(O13,11,1)*3+MID(O13,12,1)*2,11)<2,0,11-MOD(MID(O13,1,1)*5+MID(O13,2,1)*4+MID(O13,3,1)*3+MID(O13,4,1)*2+MID(O13,5,1)*9+MID(O13,6,1)*8+MID(O13,7,1)*7+MID(O13,8,1)*6+MID(O13,9,1)*5+MID(O13,10,1)*4+MID(O13,11,1)*3+MID(O13,12,1)*2,11)) -> 8 | Q13: =IF(MOD(MID(O13,1,1)*6+MID(O13,2,1)*5+MID(O13,3,1)*4+MID(O13,4,1)*3+MID(O13,5,1)*2+MID(O13,6,1)*9+MID(O13,7,1)*8+MID(O13,8,1)*7+MID(O13,9,1)*6+MID(O13,10,1)*5+MID(O13,11,1)*4+MID(O13,12,1)*3+P13*2,11)<2,0,11-MOD(MID(O13,1,1)*6+MID(O13,2,1)*5+MID(O13,3,1)*4+MID(O13,4,1)*3+MID(O13,5,1)*2+MID(O13,6,1)*9+MID(O13,7,1)*8+MID(O13,8,1)*7+MID(O13,9,1)*6+MID(O13,10,1)*5+MID(O13,11,1)*4+MID(O13,12,1)*3+P13*2,11)) -> 8 | R13: =MID(O13,1,2)&"."&MID(O13,3,3)&"."&MID(O13,6,3)&"/"&MID(O13,9,4)&"-"&TEXT(P13,"0")&TEXT(Q13,"0") -> 10.923.833/0001-88 | S13: Inapta/Baixada | T13: =IF(S13="","",IF(S13="Cadastrou","",XLOOKUP(S13,$BA$2:$BA$6,$BB$2:$BB$6,""))) | U13: =IF(S13="","",IF(S13="Cadastrou","",XLOOKUP(S13,$BA$2:$BA$6,$BC$2:$BC$6,""))) | V13: =IF(S13="","",XLOOKUP(S13,$BA$2:$BA$6,$BD$2:$BD$6,"")) | AA13: =IF(Y13="","",IF(INT(TODAY()-Y13)<0,"⚠️ Data futura",INT(TODAY()-Y13))) | AB13: =IF(AA13="","",IF(Z13="",IF(AA13>14,"🔴 Atrasado",IF(AA13>7,"🟡 Atenção","🟢 Em dia")),IF(TODAY()>Z13,"🔴 Atrasado",IF(Z13-TODAY()<=3,"🟡 Atenção","🟢 Em dia")))) | AD13: =IF(OR(AC13="",H13=""),"",H13*AC13) | AF13: =IF(AC13>0,AC13,'⚙️ Config'!$B$10) -> 0.0075 | AG13: =H13*AF13 -> 271657.23 | AH13: =AG13*'⚙️ Config'!$B$11 -> 1358286.1 | AI13: =AH13*'⚙️ Config'!$B$12 -> 407485.84
A14: 11 | B14: ANA MAIS CONSULTORIA LTDA | C14: SP | D14: 19071758 | E14: 59.76 | F14: 🔴 ALTA | G14: R$ 30-50M | H14: 32608457 | I14: 1 | J14: 1.3 | K14: 2024 | L14: Receita da dívida ativa - IRRF | M14: 2024 | N14: COBRANCA | O14: =TEXT(D14,"00000000")&"0001" -> 190717580001 | P14: =IF(MOD(MID(O14,1,1)*5+MID(O14,2,1)*4+MID(O14,3,1)*3+MID(O14,4,1)*2+MID(O14,5,1)*9+MID(O14,6,1)*8+MID(O14,7,1)*7+MID(O14,8,1)*6+MID(O14,9,1)*5+MID(O14,10,1)*4+MID(O14,11,1)*3+MID(O14,12,1)*2,11)<2,0,11-MOD(MID(O14,1,1)*5+MID(O14,2,1)*4+MID(O14,3,1)*3+MID(O14,4,1)*2+MID(O14,5,1)*9+MID(O14,6,1)*8+MID(O14,7,1)*7+MID(O14,8,1)*6+MID(O14,9,1)*5+MID(O14,10,1)*4+MID(O14,11,1)*3+MID(O14,12,1)*2,11)) -> 4 | Q14: =IF(MOD(MID(O14,1,1)*6+MID(O14,2,1)*5+MID(O14,3,1)*4+MID(O14,4,1)*3+MID(O14,5,1)*2+MID(O14,6,1)*9+MID(O14,7,1)*8+MID(O14,8,1)*7+MID(O14,9,1)*6+MID(O14,10,1)*5+MID(O14,11,1)*4+MID(O14,12,1)*3+P14*2,11)<2,0,11-MOD(MID(O14,1,1)*6+MID(O14,2,1)*5+MID(O14,3,1)*4+MID(O14,4,1)*3+MID(O14,5,1)*2+MID(O14,6,1)*9+MID(O14,7,1)*8+MID(O14,8,1)*7+MID(O14,9,1)*6+MID(O14,10,1)*5+MID(O14,11,1)*4+MID(O14,12,1)*3+P14*2,11)) -> 9 | R14: =MID(O14,1,2)&"."&MID(O14,3,3)&"."&MID(O14,6,3)&"/"&MID(O14,9,4)&"-"&TEXT(P14,"0")&TEXT(Q14,"0") -> 19.071.758/0001-49 | T14: =IF(S14="","",IF(S14="Cadastrou","",XLOOKUP(S14,$BA$2:$BA$6,$BB$2:$BB$6,""))) | U14: =IF(S14="","",IF(S14="Cadastrou","",XLOOKUP(S14,$BA$2:$BA$6,$BC$2:$BC$6,""))) | V14: =IF(S14="","",XLOOKUP(S14,$BA$2:$BA$6,$BD$2:$BD$6,"")) | AA14: =IF(Y14="","",IF(INT(TODAY()-Y14)<0,"⚠️ Data futura",INT(TODAY()-Y14))) | AB14: =IF(AA14="","",IF(Z14="",IF(AA14>14,"🔴 Atrasado",IF(AA14>7,"🟡 Atenção","🟢 Em dia")),IF(TODAY()>Z14,"🔴 Atrasado",IF(Z14-TODAY()<=3,"🟡 Atenção","🟢 Em dia")))) | AD14: =IF(OR(AC14="",H14=""),"",H14*AC14) | AF14: =IF(AC14>0,AC14,'⚙️ Config'!$B$10) -> 0.0075 | AG14: =H14*AF14 -> 244563.43 | AH14: =AG14*'⚙️ Config'!$B$11 -> 1222817.1 | AI14: =AH14*'⚙️ Config'!$B$12 -> 366845.14
A15: 12 | B15: OVS IMPORTADORA LTDA. | C15: SP | D15: 03394819 | E15: 53.17 | F15: 🔴 ALTA | G15: R$ 20-30M | H15: 29079824 | I15: 2 | J15: 1.8 | K15: 2025 | L15: Receita da dívida ativa - Outras multas | M15: 2024 | N15: AJUIZADA_SEM_GAR|COBRANCA | O15: =TEXT(D15,"00000000")&"0001" -> 033948190001 | P15: =IF(MOD(MID(O15,1,1)*5+MID(O15,2,1)*4+MID(O15,3,1)*3+MID(O15,4,1)*2+MID(O15,5,1)*9+MID(O15,6,1)*8+MID(O15,7,1)*7+MID(O15,8,1)*6+MID(O15,9,1)*5+MID(O15,10,1)*4+MID(O15,11,1)*3+MID(O15,12,1)*2,11)<2,0,11-MOD(MID(O15,1,1)*5+MID(O15,2,1)*4+MID(O15,3,1)*3+MID(O15,4,1)*2+MID(O15,5,1)*9+MID(O15,6,1)*8+MID(O15,7,1)*7+MID(O15,8,1)*6+MID(O15,9,1)*5+MID(O15,10,1)*4+MID(O15,11,1)*3+MID(O15,12,1)*2,11)) -> 7 | Q15: =IF(MOD(MID(O15,1,1)*6+MID(O15,2,1)*5+MID(O15,3,1)*4+MID(O15,4,1)*3+MID(O15,5,1)*2+MID(O15,6,1)*9+MID(O15,7,1)*8+MID(O15,8,1)*7+MID(O15,9,1)*6+MID(O15,10,1)*5+MID(O15,11,1)*4+MID(O15,12,1)*3+P15*2,11)<2,0,11-MOD(MID(O15,1,1)*6+MID(O15,2,1)*5+MID(O15,3,1)*4+MID(O15,4,1)*3+MID(O15,5,1)*2+MID(O15,6,1)*9+MID(O15,7,1)*8+MID(O15,8,1)*7+MID(O15,9,1)*6+MID(O15,10,1)*5+MID(O15,11,1)*4+MID(O15,12,1)*3+P15*2,11)) -> 9 | R15: =MID(O15,1,2)&"."&MID(O15,3,3)&"."&MID(O15,6,3)&"/"&MID(O15,9,4)&"-"&TEXT(P15,"0")&TEXT(Q15,"0") -> 03.394.819/0001-79 | T15: =IF(S15="","",IF(S15="Cadastrou","",XLOOKUP(S15,$BA$2:$BA$6,$BB$2:$BB$6,""))) | U15: =IF(S15="","",IF(S15="Cadastrou","",XLOOKUP(S15,$BA$2:$BA$6,$BC$2:$BC$6,""))) | V15: =IF(S15="","",XLOOKUP(S15,$BA$2:$BA$6,$BD$2:$BD$6,"")) | AA15: =IF(Y15="","",IF(INT(TODAY()-Y15)<0,"⚠️ Data futura",INT(TODAY()-Y15))) | AB15: =IF(AA15="","",IF(Z15="",IF(AA15>14,"🔴 Atrasado",IF(AA15>7,"🟡 Atenção","🟢 Em dia")),IF(TODAY()>Z15,"🔴 Atrasado",IF(Z15-TODAY()<=3,"🟡 Atenção","🟢 Em dia")))) | AD15: =IF(OR(AC15="",H15=""),"",H15*AC15) | AF15: =IF(AC15>0,AC15,'⚙️ Config'!$B$10) -> 0.0075 | AG15: =H15*AF15 -> 218098.68 | AH15: =AG15*'⚙️ Config'!$B$11 -> 1090493.4 | AI15: =AH15*'⚙️ Config'!$B$12 -> 327148.02 | AJ15: 12952000 | AK15: Médio | AL15: Não | AO15: Francisco Emerson Maximiniano | AP15: Socio
A16: 13 | B16: WANMIX LTDA | C16: SP | D16: 17481813 | E16: 42.59 | F16: 🔴 ALTA | G16: R$ 20-30M | H16: 28863838 | I16: 2 | J16: 1.7 | K16: 2024 | L16: Receita da dívida ativa - CSLL | Receita da dívida ativa - IRPJ | M16: 2024 | N16: AJUIZADA_SEM_GAR | O16: =TEXT(D16,"00000000")&"0001" -> 174818130001 | P16: =IF(MOD(MID(O16,1,1)*5+MID(O16,2,1)*4+MID(O16,3,1)*3+MID(O16,4,1)*2+MID(O16,5,1)*9+MID(O16,6,1)*8+MID(O16,7,1)*7+MID(O16,8,1)*6+MID(O16,9,1)*5+MID(O16,10,1)*4+MID(O16,11,1)*3+MID(O16,12,1)*2,11)<2,0,11-MOD(MID(O16,1,1)*5+MID(O16,2,1)*4+MID(O16,3,1)*3+MID(O16,4,1)*2+MID(O16,5,1)*9+MID(O16,6,1)*8+MID(O16,7,1)*7+MID(O16,8,1)*6+MID(O16,9,1)*5+MID(O16,10,1)*4+MID(O16,11,1)*3+MID(O16,12,1)*2,11)) -> 4 | Q16: =IF(MOD(MID(O16,1,1)*6+MID(O16,2,1)*5+MID(O16,3,1)*4+MID(O16,4,1)*3+MID(O16,5,1)*2+MID(O16,6,1)*9+MID(O16,7,1)*8+MID(O16,8,1)*7+MID(O16,9,1)*6+MID(O16,10,1)*5+MID(O16,11,1)*4+MID(O16,12,1)*3+P16*2,11)<2,0,11-MOD(MID(O16,1,1)*6+MID(O16,2,1)*5+MID(O16,3,1)*4+MID(O16,4,1)*3+MID(O16,5,1)*2+MID(O16,6,1)*9+MID(O16,7,1)*8+MID(O16,8,1)*7+MID(O16,9,1)*6+MID(O16,10,1)*5+MID(O16,11,1)*4+MID(O16,12,1)*3+P16*2,11)) -> 3 | R16: =MID(O16,1,2)&"."&MID(O16,3,3)&"."&MID(O16,6,3)&"/"&MID(O16,9,4)&"-"&TEXT(P16,"0")&TEXT(Q16,"0") -> 17.481.813/0001-43 | T16: =IF(S16="","",IF(S16="Cadastrou","",XLOOKUP(S16,$BA$2:$BA$6,$BB$2:$BB$6,""))) | U16: =IF(S16="","",IF(S16="Cadastrou","",XLOOKUP(S16,$BA$2:$BA$6,$BC$2:$BC$6,""))) | V16: =IF(S16="","",XLOOKUP(S16,$BA$2:$BA$6,$BD$2:$BD$6,"")) | AA16: =IF(Y16="","",IF(INT(TODAY()-Y16)<0,"⚠️ Data futura",INT(TODAY()-Y16))) | AB16: =IF(AA16="","",IF(Z16="",IF(AA16>14,"🔴 Atrasado",IF(AA16>7,"🟡 Atenção","🟢 Em dia")),IF(TODAY()>Z16,"🔴 Atrasado",IF(Z16-TODAY()<=3,"🟡 Atenção","🟢 Em dia")))) | AD16: =IF(OR(AC16="",H16=""),"",H16*AC16) | AF16: =IF(AC16>0,AC16,'⚙️ Config'!$B$10) -> 0.0075 | AG16: =H16*AF16 -> 216478.78 | AH16: =AG16*'⚙️ Config'!$B$11 -> 1082393.9 | AI16: =AH16*'⚙️ Config'!$B$12 -> 324718.18 | AJ16: 4500000
A17: 14 | B17: CTR METAIS PRECIOSOS LTDA | C17: SP | D17: 45685839 | E17: 84.39 | F17: 🔴 ALTA | G17: R$ 20-30M | H17: 28256455 | I17: 1 | J17: 0.6 | K17: 2025 | L17: R D Ativa - Multa Isolada | M17: 2025 | N17: COBRANCA | O17: =TEXT(D17,"00000000")&"0001" -> 456858390001 | P17: =IF(MOD(MID(O17,1,1)*5+MID(O17,2,1)*4+MID(O17,3,1)*3+MID(O17,4,1)*2+MID(O17,5,1)*9+MID(O17,6,1)*8+MID(O17,7,1)*7+MID(O17,8,1)*6+MID(O17,9,1)*5+MID(O17,10,1)*4+MID(O17,11,1)*3+MID(O17,12,1)*2,11)<2,0,11-MOD(MID(O17,1,1)*5+MID(O17,2,1)*4+MID(O17,3,1)*3+MID(O17,4,1)*2+MID(O17,5,1)*9+MID(O17,6,1)*8+MID(O17,7,1)*7+MID(O17,8,1)*6+MID(O17,9,1)*5+MID(O17,10,1)*4+MID(O17,11,1)*3+MID(O17,12,1)*2,11)) -> 4 | Q17: =IF(MOD(MID(O17,1,1)*6+MID(O17,2,1)*5+MID(O17,3,1)*4+MID(O17,4,1)*3+MID(O17,5,1)*2+MID(O17,6,1)*9+MID(O17,7,1)*8+MID(O17,8,1)*7+MID(O17,9,1)*6+MID(O17,10,1)*5+MID(O17,11,1)*4+MID(O17,12,1)*3+P17*2,11)<2,0,11-MOD(MID(O17,1,1)*6+MID(O17,2,1)*5+MID(O17,3,1)*4+MID(O17,4,1)*3+MID(O17,5,1)*2+MID(O17,6,1)*9+MID(O17,7,1)*8+MID(O17,8,1)*7+MID(O17,9,1)*6+MID(O17,10,1)*5+MID(O17,11,1)*4+MID(O17,12,1)*3+P17*2,11)) -> 9 | R17: =MID(O17,1,2)&"."&MID(O17,3,3)&"."&MID(O17,6,3)&"/"&MID(O17,9,4)&"-"&TEXT(P17,"0")&TEXT(Q17,"0") -> 45.685.839/0001-49 | T17: =IF(S17="","",IF(S17="Cadastrou","",XLOOKUP(S17,$BA$2:$BA$6,$BB$2:$BB$6,""))) | U17: =IF(S17="","",IF(S17="Cadastrou","",XLOOKUP(S17,$BA$2:$BA$6,$BC$2:$BC$6,""))) | V17: =IF(S17="","",XLOOKUP(S17,$BA$2:$BA$6,$BD$2:$BD$6,"")) | AA17: =IF(Y17="","",IF(INT(TODAY()-Y17)<0,"⚠️ Data futura",INT(TODAY()-Y17))) | AB17: =IF(AA17="","",IF(Z17="",IF(AA17>14,"🔴 Atrasado",IF(AA17>7,"🟡 Atenção","🟢 Em dia")),IF(TODAY()>Z17,"🔴 Atrasado",IF(Z17-TODAY()<=3,"🟡 Atenção","🟢 Em dia")))) | AD17: =IF(OR(AC17="",H17=""),"",H17*AC17) | AF17: =IF(AC17>0,AC17,'⚙️ Config'!$B$10) -> 0.0075 | AG17: =H17*AF17 -> 211923.41 | AH17: =AG17*'⚙️ Config'!$B$11 -> 1059617.1 | AI17: =AH17*'⚙️ Config'!$B$12 -> 317885.12
A18: 15 | B18: VETOR COMERCIO DE COMBUSTIVEIS LTDA | C18: MS | D18: 04677033 | E18: 59.64 | F18: 🔴 ALTA | G18: R$ 20-30M | H18: 27848766 | I18: 1 | J18: 1.3 | K18: 2024 | L18: Receita da dívida ativa - IRRF | M18: 2024 | N18: AJUIZADA_SEM_GAR | O18: =TEXT(D18,"00000000")&"0001" -> 046770330001 | P18: =IF(MOD(MID(O18,1,1)*5+MID(O18,2,1)*4+MID(O18,3,1)*3+MID(O18,4,1)*2+MID(O18,5,1)*9+MID(O18,6,1)*8+MID(O18,7,1)*7+MID(O18,8,1)*6+MID(O18,9,1)*5+MID(O18,10,1)*4+MID(O18,11,1)*3+MID(O18,12,1)*2,11)<2,0,11-MOD(MID(O18,1,1)*5+MID(O18,2,1)*4+MID(O18,3,1)*3+MID(O18,4,1)*2+MID(O18,5,1)*9+MID(O18,6,1)*8+MID(O18,7,1)*7+MID(O18,8,1)*6+MID(O18,9,1)*5+MID(O18,10,1)*4+MID(O18,11,1)*3+MID(O18,12,1)*2,11)) -> 2 | Q18: =IF(MOD(MID(O18,1,1)*6+MID(O18,2,1)*5+MID(O18,3,1)*4+MID(O18,4,1)*3+MID(O18,5,1)*2+MID(O18,6,1)*9+MID(O18,7,1)*8+MID(O18,8,1)*7+MID(O18,9,1)*6+MID(O18,10,1)*5+MID(O18,11,1)*4+MID(O18,12,1)*3+P18*2,11)<2,0,11-MOD(MID(O18,1,1)*6+MID(O18,2,1)*5+MID(O18,3,1)*4+MID(O18,4,1)*3+MID(O18,5,1)*2+MID(O18,6,1)*9+MID(O18,7,1)*8+MID(O18,8,1)*7+MID(O18,9,1)*6+MID(O18,10,1)*5+MID(O18,11,1)*4+MID(O18,12,1)*3+P18*2,11)) -> 1 | R18: =MID(O18,1,2)&"."&MID(O18,3,3)&"."&MID(O18,6,3)&"/"&MID(O18,9,4)&"-"&TEXT(P18,"0")&TEXT(Q18,"0") -> 04.677.033/0001-21 | T18: =IF(S18="","",IF(S18="Cadastrou","",XLOOKUP(S18,$BA$2:$BA$6,$BB$2:$BB$6,""))) | U18: =IF(S18="","",IF(S18="Cadastrou","",XLOOKUP(S18,$BA$2:$BA$6,$BC$2:$BC$6,""))) | V18: =IF(S18="","",XLOOKUP(S18,$BA$2:$BA$6,$BD$2:$BD$6,"")) | AA18: =IF(Y18="","",IF(INT(TODAY()-Y18)<0,"⚠️ Data futura",INT(TODAY()-Y18))) | AB18: =IF(AA18="","",IF(Z18="",IF(AA18>14,"🔴 Atrasado",IF(AA18>7,"🟡 Atenção","🟢 Em dia")),IF(TODAY()>Z18,"🔴 Atrasado",IF(Z18-TODAY()<=3,"🟡 Atenção","🟢 Em dia")))) | AD18: =IF(OR(AC18="",H18=""),"",H18*AC18) | AF18: =IF(AC18>0,AC18,'⚙️ Config'!$B$10) -> 0.0075 | AG18: =H18*AF18 -> 208865.75 | AH18: =AG18*'⚙️ Config'!$B$11 -> 1044328.7 | AI18: =AH18*'⚙️ Config'!$B$12 -> 313298.62 | AJ18: 5147975 | AL18: Não
A19: 16 | B19: SUMATRA COMERCIO EXTERIOR LTDA | C19: SP | D19: 31235518 | E19: 54 | F19: 🔴 ALTA | G19: R$ 20-30M | H19: 24915563 | I19: 1 | J19: 1.6 | K19: 2024 | L19: Receita da dívida ativa - IRPJ | M19: 2024 | N19: AJUIZADA_SEM_GAR | O19: =TEXT(D19,"00000000")&"0001" -> 312355180001 | P19: =IF(MOD(MID(O19,1,1)*5+MID(O19,2,1)*4+MID(O19,3,1)*3+MID(O19,4,1)*2+MID(O19,5,1)*9+MID(O19,6,1)*8+MID(O19,7,1)*7+MID(O19,8,1)*6+MID(O19,9,1)*5+MID(O19,10,1)*4+MID(O19,11,1)*3+MID(O19,12,1)*2,11)<2,0,11-MOD(MID(O19,1,1)*5+MID(O19,2,1)*4+MID(O19,3,1)*3+MID(O19,4,1)*2+MID(O19,5,1)*9+MID(O19,6,1)*8+MID(O19,7,1)*7+MID(O19,8,1)*6+MID(O19,9,1)*5+MID(O19,10,1)*4+MID(O19,11,1)*3+MID(O19,12,1)*2,11)) -> 3 | Q19: =IF(MOD(MID(O19,1,1)*6+MID(O19,2,1)*5+MID(O19,3,1)*4+MID(O19,4,1)*3+MID(O19,5,1)*2+MID(O19,6,1)*9+MID(O19,7,1)*8+MID(O19,8,1)*7+MID(O19,9,1)*6+MID(O19,10,1)*5+MID(O19,11,1)*4+MID(O19,12,1)*3+P19*2,11)<2,0,11-MOD(MID(O19,1,1)*6+MID(O19,2,1)*5+MID(O19,3,1)*4+MID(O19,4,1)*3+MID(O19,5,1)*2+MID(O19,6,1)*9+MID(O19,7,1)*8+MID(O19,8,1)*7+MID(O19,9,1)*6+MID(O19,10,1)*5+MID(O19,11,1)*4+MID(O19,12,1)*3+P19*2,11)) -> 8 | R19: =MID(O19,1,2)&"."&MID(O19,3,3)&"."&MID(O19,6,3)&"/"&MID(O19,9,4)&"-"&TEXT(P19,"0")&TEXT(Q19,"0") -> 31.235.518/0001-38 | T19: =IF(S19="","",IF(S19="Cadastrou","",XLOOKUP(S19,$BA$2:$BA$6,$BB$2:$BB$6,""))) | U19: =IF(S19="","",IF(S19="Cadastrou","",XLOOKUP(S19,$BA$2:$BA$6,$BC$2:$BC$6,""))) | V19: =IF(S19="","",XLOOKUP(S19,$BA$2:$BA$6,$BD$2:$BD$6,"")) | AA19: =IF(Y19="","",IF(INT(TODAY()-Y19)<0,"⚠️ Data futura",INT(TODAY()-Y19))) | AB19: =IF(AA19="","",IF(Z19="",IF(AA19>14,"🔴 Atrasado",IF(AA19>7,"🟡 Atenção","🟢 Em dia")),IF(TODAY()>Z19,"🔴 Atrasado",IF(Z19-TODAY()<=3,"🟡 Atenção","🟢 Em dia")))) | AD19: =IF(OR(AC19="",H19=""),"",H19*AC19) | AF19: =IF(AC19>0,AC19,'⚙️ Config'!$B$10) -> 0.0075 | AG19: =H19*AF19 -> 186866.73 | AH19: =AG19*'⚙️ Config'!$B$11 -> 934333.63 | AI19: =AH19*'⚙️ Config'!$B$12 -> 280300.09 | AJ19: 9903208 | AL19: Não | AM19: 19 3661-9928 | AO19: Jose Roberto Zerneri
A20: 17 | B20: BARSOTTI SERVICOS DE PORTARIA LTDA | C20: SP | D20: 10468394 | E20: 69.71 | F20: 🔴 ALTA | G20: R$ 20-30M | H20: 24685772 | I20: 1 | J20: 1.6 | K20: 2025 | L20: Receita da dívida ativa - COFINS | R D Ativa - Contribuição Empresa/Empregador | R D Ativa - Multa Isolada | M20: 2024 | N20: AJUIZADA_SEM_GAR|OUTROS | O20: =TEXT(D20,"00000000")&"0001" -> 104683940001 | P20: =IF(MOD(MID(O20,1,1)*5+MID(O20,2,1)*4+MID(O20,3,1)*3+MID(O20,4,1)*2+MID(O20,5,1)*9+MID(O20,6,1)*8+MID(O20,7,1)*7+MID(O20,8,1)*6+MID(O20,9,1)*5+MID(O20,10,1)*4+MID(O20,11,1)*3+MID(O20,12,1)*2,11)<2,0,11-MOD(MID(O20,1,1)*5+MID(O20,2,1)*4+MID(O20,3,1)*3+MID(O20,4,1)*2+MID(O20,5,1)*9+MID(O20,6,1)*8+MID(O20,7,1)*7+MID(O20,8,1)*6+MID(O20,9,1)*5+MID(O20,10,1)*4+MID(O20,11,1)*3+MID(O20,12,1)*2,11)) -> 6 | Q20: =IF(MOD(MID(O20,1,1)*6+MID(O20,2,1)*5+MID(O20,3,1)*4+MID(O20,4,1)*3+MID(O20,5,1)*2+MID(O20,6,1)*9+MID(O20,7,1)*8+MID(O20,8,1)*7+MID(O20,9,1)*6+MID(O20,10,1)*5+MID(O20,11,1)*4+MID(O20,12,1)*3+P20*2,11)<2,0,11-MOD(MID(O20,1,1)*6+MID(O20,2,1)*5+MID(O20,3,1)*4+MID(O20,4,1)*3+MID(O20,5,1)*2+MID(O20,6,1)*9+MID(O20,7,1)*8+MID(O20,8,1)*7+MID(O20,9,1)*6+MID(O20,10,1)*5+MID(O20,11,1)*4+MID(O20,12,1)*3+P20*2,11)) -> 0 | R20: 8759416 | T20: =IF(S20="","",IF(S20="Cadastrou","",XLOOKUP(S20,$BA$2:$BA$6,$BB$2:$BB$6,""))) | U20: =IF(S20="","",IF(S20="Cadastrou","",XLOOKUP(S20,$BA$2:$BA$6,$BC$2:$BC$6,""))) | V20: =IF(S20="","",XLOOKUP(S20,$BA$2:$BA$6,$BD$2:$BD$6,"")) | AA20: =IF(Y20="","",IF(INT(TODAY()-Y20)<0,"⚠️ Data futura",INT(TODAY()-Y20))) | AB20: =IF(AA20="","",IF(Z20="",IF(AA20>14,"🔴 Atrasado",IF(AA20>7,"🟡 Atenção","🟢 Em dia")),IF(TODAY()>Z20,"🔴 Atrasado",IF(Z20-TODAY()<=3,"🟡 Atenção","🟢 Em dia")))) | AD20: =IF(OR(AC20="",H20=""),"",H20*AC20) | AF20: =IF(AC20>0,AC20,'⚙️ Config'!$B$10) -> 0.0075 | AG20: =H20*AF20 -> 185143.29 | AH20: =AG20*'⚙️ Config'!$B$11 -> 925716.45 | AI20: =AH20*'⚙️ Config'!$B$12 -> 277714.94 | AJ20: 990000 | AM20: (11) 2339-6642 | AN20: rh@grupobarsotti.com.br | AO20: JOSE VALDIR DE OLIVEIRA | AP20: Sócio-Administrador
A21: 18 | B21: KOPRUM INDUSTRIA E COMERCIO SA | C21: SP | D21: 08759416 | E21: 57.49 | F21: 🔴 ALTA | G21: R$ 20-30M | H21: 24060892 | I21: 1 | J21: 1.4 | K21: 2024 | L21: Receita da dívida ativa - CSLL | M21: 2024 | N21: AJUIZADA_SEM_GAR | O21: =TEXT(D21,"00000000")&"0001" -> 087594160001 | P21: =IF(MOD(MID(O21,1,1)*5+MID(O21,2,1)*4+MID(O21,3,1)*3+MID(O21,4,1)*2+MID(O21,5,1)*9+MID(O21,6,1)*8+MID(O21,7,1)*7+MID(O21,8,1)*6+MID(O21,9,1)*5+MID(O21,10,1)*4+MID(O21,11,1)*3+MID(O21,12,1)*2,11)<2,0,11-MOD(MID(O21,1,1)*5+MID(O21,2,1)*4+MID(O21,3,1)*3+MID(O21,4,1)*2+MID(O21,5,1)*9+MID(O21,6,1)*8+MID(O21,7,1)*7+MID(O21,8,1)*6+MID(O21,9,1)*5+MID(O21,10,1)*4+MID(O21,11,1)*3+MID(O21,12,1)*2,11)) -> 0 | Q21: =IF(MOD(MID(O21,1,1)*6+MID(O21,2,1)*5+MID(O21,3,1)*4+MID(O21,4,1)*3+MID(O21,5,1)*2+MID(O21,6,1)*9+MID(O21,7,1)*8+MID(O21,8,1)*7+MID(O21,9,1)*6+MID(O21,10,1)*5+MID(O21,11,1)*4+MID(O21,12,1)*3+P21*2,11)<2,0,11-MOD(MID(O21,1,1)*6+MID(O21,2,1)*5+MID(O21,3,1)*4+MID(O21,4,1)*3+MID(O21,5,1)*2+MID(O21,6,1)*9+MID(O21,7,1)*8+MID(O21,8,1)*7+MID(O21,9,1)*6+MID(O21,10,1)*5+MID(O21,11,1)*4+MID(O21,12,1)*3+P21*2,11)) -> 8 | R21: =MID(O21,1,2)&"."&MID(O21,3,3)&"."&MID(O21,6,3)&"/"&MID(O21,9,4)&"-"&TEXT(P21,"0")&TEXT(Q21,"0") -> 08.759.416/0001-08 | T21: =IF(S21="","",IF(S21="Cadastrou","",XLOOKUP(S21,$BA$2:$BA$6,$BB$2:$BB$6,""))) | U21: =IF(S21="","",IF(S21="Cadastrou","",XLOOKUP(S21,$BA$2:$BA$6,$BC$2:$BC$6,""))) | V21: =IF(S21="","",XLOOKUP(S21,$BA$2:$BA$6,$BD$2:$BD$6,"")) | AA21: =IF(Y21="","",IF(INT(TODAY()-Y21)<0,"⚠️ Data futura",INT(TODAY()-Y21))) | AB21: =IF(AA21="","",IF(Z21="",IF(AA21>14,"🔴 Atrasado",IF(AA21>7,"🟡 Atenção","🟢 Em dia")),IF(TODAY()>Z21,"🔴 Atrasado",IF(Z21-TODAY()<=3,"🟡 Atenção","🟢 Em dia")))) | AD21: =IF(OR(AC21="",H21=""),"",H21*AC21) | AF21: =IF(AC21>0,AC21,'⚙️ Config'!$B$10) -> 0.0075 | AG21: =H21*AF21 -> 180456.69 | AH21: =AG21*'⚙️ Config'!$B$11 -> 902283.46 | AI21: =AH21*'⚙️ Config'!$B$12 -> 270685.04 | AJ21: 17580000 | AM21: (31) 3438-7904 | AN21: legalizacao@britt.com.br | AO21: PAULO CESAR VERLY DA CRUZ | AP21: Diretor
A22: 19 | B22: CP CONSTRUCOES E PARTICIPACOES LTDA | C22: SP | D22: 07177497 | E22: 67.29 | F22: 🔴 ALTA | G22: R$ 20-30M | H22: 23340249 | I22: 1 | J22: 1 | K22: 2025 | L22: Receita da dívida ativa - CSLL | M22: 2025 | N22: COBRANCA | O22: =TEXT(D22,"00000000")&"0001" -> 071774970001 | P22: =IF(MOD(MID(O22,1,1)*5+MID(O22,2,1)*4+MID(O22,3,1)*3+MID(O22,4,1)*2+MID(O22,5,1)*9+MID(O22,6,1)*8+MID(O22,7,1)*7+MID(O22,8,1)*6+MID(O22,9,1)*5+MID(O22,10,1)*4+MID(O22,11,1)*3+MID(O22,12,1)*2,11)<2,0,11-MOD(MID(O22,1,1)*5+MID(O22,2,1)*4+MID(O22,3,1)*3+MID(O22,4,1)*2+MID(O22,5,1)*9+MID(O22,6,1)*8+MID(O22,7,1)*7+MID(O22,8,1)*6+MID(O22,9,1)*5+MID(O22,10,1)*4+MID(O22,11,1)*3+MID(O22,12,1)*2,11)) -> 6 | Q22: =IF(MOD(MID(O22,1,1)*6+MID(O22,2,1)*5+MID(O22,3,1)*4+MID(O22,4,1)*3+MID(O22,5,1)*2+MID(O22,6,1)*9+MID(O22,7,1)*8+MID(O22,8,1)*7+MID(O22,9,1)*6+MID(O22,10,1)*5+MID(O22,11,1)*4+MID(O22,12,1)*3+P22*2,11)<2,0,11-MOD(MID(O22,1,1)*6+MID(O22,2,1)*5+MID(O22,3,1)*4+MID(O22,4,1)*3+MID(O22,5,1)*2+MID(O22,6,1)*9+MID(O22,7,1)*8+MID(O22,8,1)*7+MID(O22,9,1)*6+MID(O22,10,1)*5+MID(O22,11,1)*4+MID(O22,12,1)*3+P22*2,11)) -> 7 | R22: =MID(O22,1,2)&"."&MID(O22,3,3)&"."&MID(O22,6,3)&"/"&MID(O22,9,4)&"-"&TEXT(P22,"0")&TEXT(Q22,"0") -> 07.177.497/0001-67 | T22: =IF(S22="","",IF(S22="Cadastrou","",XLOOKUP(S22,$BA$2:$BA$6,$BB$2:$BB$6,""))) | U22: =IF(S22="","",IF(S22="Cadastrou","",XLOOKUP(S22,$BA$2:$BA$6,$BC$2:$BC$6,""))) | V22: =IF(S22="","",XLOOKUP(S22,$BA$2:$BA$6,$BD$2:$BD$6,"")) | AA22: =IF(Y22="","",IF(INT(TODAY()-Y22)<0,"⚠️ Data futura",INT(TODAY()-Y22))) | AB22: =IF(AA22="","",IF(Z22="",IF(AA22>14,"🔴 Atrasado",IF(AA22>7,"🟡 Atenção","🟢 Em dia")),IF(TODAY()>Z22,"🔴 Atrasado",IF(Z22-TODAY()<=3,"🟡 Atenção","🟢 Em dia")))) | AD22: =IF(OR(AC22="",H22=""),"",H22*AC22) | AF22: =IF(AC22>0,AC22,'⚙️ Config'!$B$10) -> 0.0075 | AG22: =H22*AF22 -> 175051.86 | AH22: =AG22*'⚙️ Config'!$B$11 -> 875259.32 | AI22: =AH22*'⚙️ Config'!$B$12 -> 262577.8 | AJ22: 10361753 | AM22: (11) 3154-1500 | AN22: processos@swscontabil.com.br | AO22: ANDRE LOIFERMAN | AP22: Administrador
A23: 20 | B23: REGENCIA COMERCIO DE GENEROS ALIMENTICIOS LTDA | C23: SP | D23: 23866428 | E23: 57.43 | F23: 🔴 ALTA | G23: R$ 20-30M | H23: 22021035 | I23: 1 | J23: 1.4 | K23: 2024 | L23: Receita da dívida ativa - PIS | M23: 2024 | N23: AJUIZADA_SEM_GAR | O23: =TEXT(D23,"00000000")&"0001" -> 238664280001 | P23: =IF(MOD(MID(O23,1,1)*5+MID(O23,2,1)*4+MID(O23,3,1)*3+MID(O23,4,1)*2+MID(O23,5,1)*9+MID(O23,6,1)*8+MID(O23,7,1)*7+MID(O23,8,1)*6+MID(O23,9,1)*5+MID(O23,10,1)*4+MID(O23,11,1)*3+MID(O23,12,1)*2,11)<2,0,11-MOD(MID(O23,1,1)*5+MID(O23,2,1)*4+MID(O23,3,1)*3+MID(O23,4,1)*2+MID(O23,5,1)*9+MID(O23,6,1)*8+MID(O23,7,1)*7+MID(O23,8,1)*6+MID(O23,9,1)*5+MID(O23,10,1)*4+MID(O23,11,1)*3+MID(O23,12,1)*2,11)) -> 1 | Q23: =IF(MOD(MID(O23,1,1)*6+MID(O23,2,1)*5+MID(O23,3,1)*4+MID(O23,4,1)*3+MID(O23,5,1)*2+MID(O23,6,1)*9+MID(O23,7,1)*8+MID(O23,8,1)*7+MID(O23,9,1)*6+MID(O23,10,1)*5+MID(O23,11,1)*4+MID(O23,12,1)*3+P23*2,11)<2,0,11-MOD(MID(O23,1,1)*6+MID(O23,2,1)*5+MID(O23,3,1)*4+MID(O23,4,1)*3+MID(O23,5,1)*2+MID(O23,6,1)*9+MID(O23,7,1)*8+MID(O23,8,1)*7+MID(O23,9,1)*6+MID(O23,10,1)*5+MID(O23,11,1)*4+MID(O23,12,1)*3+P23*2,11)) -> 7 | R23: =MID(O23,1,2)&"."&MID(O23,3,3)&"."&MID(O23,6,3)&"/"&MID(O23,9,4)&"-"&TEXT(P23,"0")&TEXT(Q23,"0") -> 23.866.428/0001-17 | T23: =IF(S23="","",IF(S23="Cadastrou","",XLOOKUP(S23,$BA$2:$BA$6,$BB$2:$BB$6,""))) | U23: =IF(S23="","",IF(S23="Cadastrou","",XLOOKUP(S23,$BA$2:$BA$6,$BC$2:$BC$6,""))) | V23: =IF(S23="","",XLOOKUP(S23,$BA$2:$BA$6,$BD$2:$BD$6,"")) | AA23: =IF(Y23="","",IF(INT(TODAY()-Y23)<0,"⚠️ Data futura",INT(TODAY()-Y23))) | AB23: =IF(AA23="","",IF(Z23="",IF(AA23>14,"🔴 Atrasado",IF(AA23>7,"🟡 Atenção","🟢 Em dia")),IF(TODAY()>Z23,"🔴 Atrasado",IF(Z23-TODAY()<=3,"🟡 Atenção","🟢 Em dia")))) | AD23: =IF(OR(AC23="",H23=""),"",H23*AC23) | AF23: =IF(AC23>0,AC23,'⚙️ Config'!$B$10) -> 0.0075 | AG23: =H23*AF23 -> 165157.76 | AH23: =AG23*'⚙️ Config'!$B$11 -> 825788.8 | AI23: =AH23*'⚙️ Config'!$B$12 -> 247736.64 | AJ23: 1000 | AM23: (15) 3259-2634 | AN23: hazdelservicos@gmail.com | AO23: MARCIUS CESAR COSTA | AP23: Sócio-Administrador
A24: 21 | B24: ORIGINAL BRASIL COMERCIO IMPORTACAO E EXPORTACAO LTDA | C24: SP | D24: 72980642 | E24: 48.57 | F24: 🔴 ALTA | G24: R$ 20-30M | H24: 21282628 | I24: 1 | J24: 2 | K24: 2024 | L24: R D Ativa - Multa Isolada | M24: 2024 | N24: AJUIZADA_SEM_GAR | O24: =TEXT(D24,"00000000")&"0001" -> 729806420001 | P24: =IF(MOD(MID(O24,1,1)*5+MID(O24,2,1)*4+MID(O24,3,1)*3+MID(O24,4,1)*2+MID(O24,5,1)*9+MID(O24,6,1)*8+MID(O24,7,1)*7+MID(O24,8,1)*6+MID(O24,9,1)*5+MID(O24,10,1)*4+MID(O24,11,1)*3+MID(O24,12,1)*2,11)<2,0,11-MOD(MID(O24,1,1)*5+MID(O24,2,1)*4+MID(O24,3,1)*3+MID(O24,4,1)*2+MID(O24,5,1)*9+MID(O24,6,1)*8+MID(O24,7,1)*7+MID(O24,8,1)*6+MID(O24,9,1)*5+MID(O24,10,1)*4+MID(O24,11,1)*3+MID(O24,12,1)*2,11)) -> 0 | Q24: =IF(MOD(MID(O24,1,1)*6+MID(O24,2,1)*5+MID(O24,3,1)*4+MID(O24,4,1)*3+MID(O24,5,1)*2+MID(O24,6,1)*9+MID(O24,7,1)*8+MID(O24,8,1)*7+MID(O24,9,1)*6+MID(O24,10,1)*5+MID(O24,11,1)*4+MID(O24,12,1)*3+P24*2,11)<2,0,11-MOD(MID(O24,1,1)*6+MID(O24,2,1)*5+MID(O24,3,1)*4+MID(O24,4,1)*3+MID(O24,5,1)*2+MID(O24,6,1)*9+MID(O24,7,1)*8+MID(O24,8,1)*7+MID(O24,9,1)*6+MID(O24,10,1)*5+MID(O24,11,1)*4+MID(O24,12,1)*3+P24*2,11)) -> 5 | R24: =MID(O24,1,2)&"."&MID(O24,3,3)&"."&MID(O24,6,3)&"/"&MID(O24,9,4)&"-"&TEXT(P24,"0")&TEXT(Q24,"0") -> 72.980.642/0001-05 | T24: =IF(S24="","",IF(S24="Cadastrou","",XLOOKUP(S24,$BA$2:$BA$6,$BB$2:$BB$6,""))) | U24: =IF(S24="","",IF(S24="Cadastrou","",XLOOKUP(S24,$BA$2:$BA$6,$BC$2:$BC$6,""))) | V24: =IF(S24="","",XLOOKUP(S24,$BA$2:$BA$6,$BD$2:$BD$6,"")) | AA24: =IF(Y24="","",IF(INT(TODAY()-Y24)<0,"⚠️ Data futura",INT(TODAY()-Y24))) | AB24: =IF(AA24="","",IF(Z24="",IF(AA24>14,"🔴 Atrasado",IF(AA24>7,"🟡 Atenção","🟢 Em dia")),IF(TODAY()>Z24,"🔴 Atrasado",IF(Z24-TODAY()<=3,"🟡 Atenção","🟢 Em dia")))) | AD24: =IF(OR(AC24="",H24=""),"",H24*AC24) | AF24: =IF(AC24>0,AC24,'⚙️ Config'!$B$10) -> 0.0075 | AG24: =H24*AF24 -> 159619.71 | AH24: =AG24*'⚙️ Config'!$B$11 -> 798098.54 | AI24: =AH24*'⚙️ Config'!$B$12 -> 239429.56 | AJ24: 600000 | AM24: (11) 2657-4485 | AN24: apoio@originalbr.com.br | AO24: APARECIDO DONIZETI DA SILVA | AP24: Sócio-Administrador
A25: 22 | B25: VLADS INTERMEDIACOES E SERVICOS ADMINISTRATIVOS LTDA | C25: SP | D25: 28365646 | E25: 43.87 | F25: 🔴 ALTA | G25: R$ 20-30M | H25: 20121101 | I25: 2 | J25: 1.6 | K25: 2024 | L25: Receita da dívida ativa - CSLL | Receita da dívida ativa - IRPJ | M25: 2024 | N25: COBRANCA | O25: =TEXT(D25,"00000000")&"0001" -> 283656460001 | P25: =IF(MOD(MID(O25,1,1)*5+MID(O25,2,1)*4+MID(O25,3,1)*3+MID(O25,4,1)*2+MID(O25,5,1)*9+MID(O25,6,1)*8+MID(O25,7,1)*7+MID(O25,8,1)*6+MID(O25,9,1)*5+MID(O25,10,1)*4+MID(O25,11,1)*3+MID(O25,12,1)*2,11)<2,0,11-MOD(MID(O25,1,1)*5+MID(O25,2,1)*4+MID(O25,3,1)*3+MID(O25,4,1)*2+MID(O25,5,1)*9+MID(O25,6,1)*8+MID(O25,7,1)*7+MID(O25,8,1)*6+MID(O25,9,1)*5+MID(O25,10,1)*4+MID(O25,11,1)*3+MID(O25,12,1)*2,11)) -> 9 | Q25: =IF(MOD(MID(O25,1,1)*6+MID(O25,2,1)*5+MID(O25,3,1)*4+MID(O25,4,1)*3+MID(O25,5,1)*2+MID(O25,6,1)*9+MID(O25,7,1)*8+MID(O25,8,1)*7+MID(O25,9,1)*6+MID(O25,10,1)*5+MID(O25,11,1)*4+MID(O25,12,1)*3+P25*2,11)<2,0,11-MOD(MID(O25,1,1)*6+MID(O25,2,1)*5+MID(O25,3,1)*4+MID(O25,4,1)*3+MID(O25,5,1)*2+MID(O25,6,1)*9+MID(O25,7,1)*8+MID(O25,8,1)*7+MID(O25,9,1)*6+MID(O25,10,1)*5+MID(O25,11,1)*4+MID(O25,12,1)*3+P25*2,11)) -> 1 | R25: =MID(O25,1,2)&"."&MID(O25,3,3)&"."&MID(O25,6,3)&"/"&MID(O25,9,4)&"-"&TEXT(P25,"0")&TEXT(Q25,"0") -> 28.365.646/0001-91 | T25: =IF(S25="","",IF(S25="Cadastrou","",XLOOKUP(S25,$BA$2:$BA$6,$BB$2:$BB$6,""))) | U25: =IF(S25="","",IF(S25="Cadastrou","",XLOOKUP(S25,$BA$2:$BA$6,$BC$2:$BC$6,""))) | V25: =IF(S25="","",XLOOKUP(S25,$BA$2:$BA$6,$BD$2:$BD$6,"")) | AA25: =IF(Y25="","",IF(INT(TODAY()-Y25)<0,"⚠️ Data futura",INT(TODAY()-Y25))) | AB25: =IF(AA25="","",IF(Z25="",IF(AA25>14,"🔴 Atrasado",IF(AA25>7,"🟡 Atenção","🟢 Em dia")),IF(TODAY()>Z25,"🔴 Atrasado",IF(Z25-TODAY()<=3,"🟡 Atenção","🟢 Em dia")))) | AD25: =IF(OR(AC25="",H25=""),"",H25*AC25) | AF25: =IF(AC25>0,AC25,'⚙️ Config'!$B$10) -> 0.0075 | AG25: =H25*AF25 -> 150908.26 | AH25: =AG25*'⚙️ Config'!$B$11 -> 754541.3 | AI25: =AH25*'⚙️ Config'!$B$12 -> 226362.39 | AJ25: 150000 | AM25: (11) 3500-9994 | AN25: contato@dacbrasil.com | AO25: VLADMIR RODRIGUES DE SALES | AP25: Sócio-Administrador
A26: 23 | B26: ICBA INDUSTRIA E COMERCIO DE BANCOS AUTOMOTIVOS LTDA. | C26: SP | D26: 51966612 | E26: 47.37 | F26: 🔴 ALTA | G26: R$ 10-20M | H26: 19721771 | I26: 2 | J26: 1.4 | K26: 2024 | L26: Receita da dívida ativa - Imposto de Importação | IPI - Receita da dívida ativa | M26: 2024 | N26: AJUIZADA_SEM_GAR | O26: =TEXT(D26,"00000000")&"0001" -> 519666120001 | P26: =IF(MOD(MID(O26,1,1)*5+MID(O26,2,1)*4+MID(O26,3,1)*3+MID(O26,4,1)*2+MID(O26,5,1)*9+MID(O26,6,1)*8+MID(O26,7,1)*7+MID(O26,8,1)*6+MID(O26,9,1)*5+MID(O26,10,1)*4+MID(O26,11,1)*3+MID(O26,12,1)*2,11)<2,0,11-MOD(MID(O26,1,1)*5+MID(O26,2,1)*4+MID(O26,3,1)*3+MID(O26,4,1)*2+MID(O26,5,1)*9+MID(O26,6,1)*8+MID(O26,7,1)*7+MID(O26,8,1)*6+MID(O26,9,1)*5+MID(O26,10,1)*4+MID(O26,11,1)*3+MID(O26,12,1)*2,11)) -> 7 | Q26: =IF(MOD(MID(O26,1,1)*6+MID(O26,2,1)*5+MID(O26,3,1)*4+MID(O26,4,1)*3+MID(O26,5,1)*2+MID(O26,6,1)*9+MID(O26,7,1)*8+MID(O26,8,1)*7+MID(O26,9,1)*6+MID(O26,10,1)*5+MID(O26,11,1)*4+MID(O26,12,1)*3+P26*2,11)<2,0,11-MOD(MID(O26,1,1)*6+MID(O26,2,1)*5+MID(O26,3,1)*4+MID(O26,4,1)*3+MID(O26,5,1)*2+MID(O26,6,1)*9+MID(O26,7,1)*8+MID(O26,8,1)*7+MID(O26,9,1)*6+MID(O26,10,1)*5+MID(O26,11,1)*4+MID(O26,12,1)*3+P26*2,11)) -> 4 | R26: =MID(O26,1,2)&"."&MID(O26,3,3)&"."&MID(O26,6,3)&"/"&MID(O26,9,4)&"-"&TEXT(P26,"0")&TEXT(Q26,"0") -> 51.966.612/0001-74 | T26: =IF(S26="","",IF(S26="Cadastrou","",XLOOKUP(S26,$BA$2:$BA$6,$BB$2:$BB$6,""))) | U26: =IF(S26="","",IF(S26="Cadastrou","",XLOOKUP(S26,$BA$2:$BA$6,$BC$2:$BC$6,""))) | V26: =IF(S26="","",XLOOKUP(S26,$BA$2:$BA$6,$BD$2:$BD$6,"")) | AA26: =IF(Y26="","",IF(INT(TODAY()-Y26)<0,"⚠️ Data futura",INT(TODAY()-Y26))) | AB26: =IF(AA26="","",IF(Z26="",IF(AA26>14,"🔴 Atrasado",IF(AA26>7,"🟡 Atenção","🟢 Em dia")),IF(TODAY()>Z26,"🔴 Atrasado",IF(Z26-TODAY()<=3,"🟡 Atenção","🟢 Em dia")))) | AD26: =IF(OR(AC26="",H26=""),"",H26*AC26) | AF26: =IF(AC26>0,AC26,'⚙️ Config'!$B$10) -> 0.0075 | AG26: =H26*AF26 -> 147913.28 | AH26: =AG26*'⚙️ Config'!$B$11 -> 739566.41 | AI26: =AH26*'⚙️ Config'!$B$12 -> 221869.92 | AJ26: 63891397 | AM26: (11) 6160-9425 | AN26: mac@keiper.com.br | AO26: CRISTINA CEZAR BASTIANELLO | AP26: Administrador
A27: 24 | B27: AGROPECUARIA PONTE ALTA LTDA | C27: MS | D27: 00983080 | E27: 61.69 | F27: 🔴 ALTA | G27: R$ 10-20M | H27: 19252926 | I27: 1 | J27: 1.2 | K27: 2024 | L27: Receita da dívida ativa - CSLL | M27: 2024 | N27: AJUIZADA_SEM_GAR | O27: =TEXT(D27,"00000000")&"0001" -> 009830800001 | P27: =IF(MOD(MID(O27,1,1)*5+MID(O27,2,1)*4+MID(O27,3,1)*3+MID(O27,4,1)*2+MID(O27,5,1)*9+MID(O27,6,1)*8+MID(O27,7,1)*7+MID(O27,8,1)*6+MID(O27,9,1)*5+MID(O27,10,1)*4+MID(O27,11,1)*3+MID(O27,12,1)*2,11)<2,0,11-MOD(MID(O27,1,1)*5+MID(O27,2,1)*4+MID(O27,3,1)*3+MID(O27,4,1)*2+MID(O27,5,1)*9+MID(O27,6,1)*8+MID(O27,7,1)*7+MID(O27,8,1)*6+MID(O27,9,1)*5+MID(O27,10,1)*4+MID(O27,11,1)*3+MID(O27,12,1)*2,11)) -> 4 | Q27: =IF(MOD(MID(O27,1,1)*6+MID(O27,2,1)*5+MID(O27,3,1)*4+MID(O27,4,1)*3+MID(O27,5,1)*2+MID(O27,6,1)*9+MID(O27,7,1)*8+MID(O27,8,1)*7+MID(O27,9,1)*6+MID(O27,10,1)*5+MID(O27,11,1)*4+MID(O27,12,1)*3+P27*2,11)<2,0,11-MOD(MID(O27,1,1)*6+MID(O27,2,1)*5+MID(O27,3,1)*4+MID(O27,4,1)*3+MID(O27,5,1)*2+MID(O27,6,1)*9+MID(O27,7,1)*8+MID(O27,8,1)*7+MID(O27,9,1)*6+MID(O27,10,1)*5+MID(O27,11,1)*4+MID(O27,12,1)*3+P27*2,11)) -> 2 | R27: =MID(O27,1,2)&"."&MID(O27,3,3)&"."&MID(O27,6,3)&"/"&MID(O27,9,4)&"-"&TEXT(P27,"0")&TEXT(Q27,"0") -> 00.983.080/0001-42 | T27: =IF(S27="","",IF(S27="Cadastrou","",XLOOKUP(S27,$BA$2:$BA$6,$BB$2:$BB$6,""))) | U27: =IF(S27="","",IF(S27="Cadastrou","",XLOOKUP(S27,$BA$2:$BA$6,$BC$2:$BC$6,""))) | V27: =IF(S27="","",XLOOKUP(S27,$BA$2:$BA$6,$BD$2:$BD$6,"")) | AA27: =IF(Y27="","",IF(INT(TODAY()-Y27)<0,"⚠️ Data futura",INT(TODAY()-Y27))) | AB27: =IF(AA27="","",IF(Z27="",IF(AA27>14,"🔴 Atrasado",IF(AA27>7,"🟡 Atenção","🟢 Em dia")),IF(TODAY()>Z27,"🔴 Atrasado",IF(Z27-TODAY()<=3,"🟡 Atenção","🟢 Em dia")))) | AD27: =IF(OR(AC27="",H27=""),"",H27*AC27) | AF27: =IF(AC27>0,AC27,'⚙️ Config'!$B$10) -> 0.0075 | AG27: =H27*AF27 -> 144396.94 | AH27: =AG27*'⚙️ Config'!$B$11 -> 721984.71 | AI27: =AH27*'⚙️ Config'!$B$12 -> 216595.41 | AJ27: 300000 | AM27: (67) 3301-7312 | AN27: esccom@terra.com.br | AO27: PAULO RENATO KOVALSKI | AP27: Sócio-Administrador
